Workbook

Sheet Правила
A1: Правила расчёта четвертной оценки
A3: Параметр | B3: Значение | C3: Пояснение
A4: Вес текущих оценок (ФО) | B4: 0.25 | C4: Средний балл из журнала ÷ 10
A5: Вес СОР | B5: 0.25 | C5: Сумма баллов за все СОР ÷ сумма максимальных баллов
A6: Вес СОЧ | B6: 0.5 | C6: Балл за СОЧ ÷ максимальный балл
A8: Порог «5», от | B8: 0.85 | C8: 85–100%
A9: Порог «4», от | B9: 0.65 | C9: 65–84%
A10: Порог «3», от | B10: 0.4 | C10: 40–64%; ниже 40% — «2»
A12: Итог % = ФО×вес + СОР×вес + СОЧ×вес. Синие значения можно менять — всё пересчитается.
A13: Отличник — «5» по алгебре и геометрии. Хорошист — обе оценки не ниже «4». Резерв — одна «3», вторая «4» или «5».
A14: Если нет балла за СОЧ, четвертная не считается (пометка «нет СОЧ»).

Sheet Четвертные
A1: Четвертные оценки — алгебра и геометрия, 1 четверть 2026/2027
A2: Класс | B2: № | C2: ФИО | D2: Алгебра | I2: Геометрия | N2: Статус
D3: ФО % | E3: СОР % | F3: СОЧ % | G3: Итог % | H3: Оценка | I3: ФО % | J3: СОР % | K3: СОЧ % | L3: Итог % | M3: Оценка
A4: 8А | B4: 1 | C4: ='8А СОР-СОЧ'!B4 | D4: =IFERROR(INDEX('8А Алгебра'!$Z:$Z,MATCH($C4,'8А Алгебра'!$B:$B,0))/10,"") | E4: =('8А СОР-СОЧ'!C4)/('8А СОР-СОЧ'!C$19) | F4: =IF('8А СОР-СОЧ'!E4="","",'8А СОР-СОЧ'!E4/'8А СОР-СОЧ'!E$19) | G4: =IF(OR(F4="",D4=""),"",D4*Правила!$B$4+E4*Правила!$B$5+F4*Правила!$B$6) | H4: =IF(G4="","нет СОЧ",IF(G4>=Правила!$B$8,5,IF(G4>=Правила!$B$9,4,IF(G4>=Правила!$B$10,3,2)))) | I4: =IFERROR(INDEX('8А Геометрия'!$S:$S,MATCH($C4,'8А Геометрия'!$B:$B,0))/10,"") | J4: =('8А СОР-СОЧ'!G4)/('8А СОР-СОЧ'!G$19) | K4: =IF('8А СОР-СОЧ'!I4="","",'8А СОР-СОЧ'!I4/'8А СОР-СОЧ'!I$19) | L4: =IF(OR(K4="",I4=""),"",I4*Правила!$B$4+J4*Правила!$B$5+K4*Правила!$B$6) | M4: =IF(L4="","нет СОЧ",IF(L4>=Правила!$B$8,5,IF(L4>=Правила!$B$9,4,IF(L4>=Правила!$B$10,3,2)))) | N4: =IF(OR(H4="нет СОЧ",M4="нет СОЧ"),"нет СОЧ",IF(AND(H4=5,M4=5),"Отличник",IF(MIN(H4,M4)>=4,"Хорошист",IF(AND(MIN(H4,M4)=3,MAX(H4,M4)>=4),"Резерв (одна «3»)",""))))
A5: 8А | B5: 2 | C5: ='8А СОР-СОЧ'!B5 | D5: =IFERROR(INDEX('8А Алгебра'!$Z:$Z,MATCH($C5,'8А Алгебра'!$B:$B,0))/10,"") | E5: =('8А СОР-СОЧ'!C5)/('8А СОР-СОЧ'!C$19) | F5: =IF('8А СОР-СОЧ'!E5="","",'8А СОР-СОЧ'!E5/'8А СОР-СОЧ'!E$19) | G5: =IF(OR(F5="",D5=""),"",D5*Правила!$B$4+E5*Правила!$B$5+F5*Правила!$B$6) | H5: =IF(G5="","нет СОЧ",IF(G5>=Правила!$B$8,5,IF(G5>=Правила!$B$9,4,IF(G5>=Правила!$B$10,3,2)))) | I5: =IFERROR(INDEX('8А Геометрия'!$S:$S,MATCH($C5,'8А Геометрия'!$B:$B,0))/10,"") | J5: =('8А СОР-СОЧ'!G5)/('8А СОР-СОЧ'!G$19) | K5: =IF('8А СОР-СОЧ'!I5="","",'8А СОР-СОЧ'!I5/'8А СОР-СОЧ'!I$19) | L5: =IF(OR(K5="",I5=""),"",I5*Правила!$B$4+J5*Правила!$B$5+K5*Правила!$B$6) | M5: =IF(L5="","нет СОЧ",IF(L5>=Правила!$B$8,5,IF(L5>=Правила!$B$9,4,IF(L5>=Правила!$B$10,3,2)))) | N5: =IF(OR(H5="нет СОЧ",M5="нет СОЧ"),"нет СОЧ",IF(AND(H5=5,M5=5),"Отличник",IF(MIN(H5,M5)>=4,"Хорошист",IF(AND(MIN(H5,M5)=3,MAX(H5,M5)>=4),"Резерв (одна «3»)",""))))
A6: 8А | B6: 3 | C6: ='8А СОР-СОЧ'!B6 | D6: =IFERROR(INDEX('8А Алгебра'!$Z:$Z,MATCH($C6,'8А Алгебра'!$B:$B,0))/10,"") | E6: =('8А СОР-СОЧ'!C6)/('8А СОР-СОЧ'!C$19) | F6: =IF('8А СОР-СОЧ'!E6="","",'8А СОР-СОЧ'!E6/'8А СОР-СОЧ'!E$19) | G6: =IF(OR(F6="",D6=""),"",D6*Правила!$B$4+E6*Правила!$B$5+F6*Правила!$B$6) | H6: =IF(G6="","нет СОЧ",IF(G6>=Правила!$B$8,5,IF(G6>=Правила!$B$9,4,IF(G6>=Правила!$B$10,3,2)))) | I6: =IFERROR(INDEX('8А Геометрия'!$S:$S,MATCH($C6,'8А Геометрия'!$B:$B,0))/10,"") | J6: =('8А СОР-СОЧ'!G6)/('8А СОР-СОЧ'!G$19) | K6: =IF('8А СОР-СОЧ'!I6="","",'8А СОР-СОЧ'!I6/'8А СОР-СОЧ'!I$19) | L6: =IF(OR(K6="",I6=""),"",I6*Правила!$B$4+J6*Правила!$B$5+K6*Правила!$B$6) | M6: =IF(L6="","нет СОЧ",IF(L6>=Правила!$B$8,5,IF(L6>=Правила!$B$9,4,IF(L6>=Правила!$B$10,3,2)))) | N6: =IF(OR(H6="нет СОЧ",M6="нет СОЧ"),"нет СОЧ",IF(AND(H6=5,M6=5),"Отличник",IF(MIN(H6,M6)>=4,"Хорошист",IF(AND(MIN(H6,M6)=3,MAX(H6,M6)>=4),"Резерв (одна «3»)",""))))
A7: 8А | B7: 4 | C7: ='8А СОР-СОЧ'!B7 | D7: =IFERROR(INDEX('8А Алгебра'!$Z:$Z,MATCH($C7,'8А Алгебра'!$B:$B,0))/10,"") | E7: =('8А СОР-СОЧ'!C7)/('8А СОР-СОЧ'!C$19) | F7: =IF('8А СОР-СОЧ'!E7="","",'8А СОР-СОЧ'!E7/'8А СОР-СОЧ'!E$19) | G7: =IF(OR(F7="",D7=""),"",D7*Правила!$B$4+E7*Правила!$B$5+F7*Правила!$B$6) | H7: =IF(G7="","нет СОЧ",IF(G7>=Правила!$B$8,5,IF(G7>=Правила!$B$9,4,IF(G7>=Правила!$B$10,3,2)))) | I7: =IFERROR(INDEX('8А Геометрия'!$S:$S,MATCH($C7,'8А Геометрия'!$B:$B,0))/10,"") | J7: =('8А СОР-СОЧ'!G7)/('8А СОР-СОЧ'!G$19) | K7: =IF('8А СОР-СОЧ'!I7="","",'8А СОР-СОЧ'!I7/'8А СОР-СОЧ'!I$19) | L7: =IF(OR(K7="",I7=""),"",I7*Правила!$B$4+J7*Правила!$B$5+K7*Правила!$B$6) | M7: =IF(L7="","нет СОЧ",IF(L7>=Правила!$B$8,5,IF(L7>=Правила!$B$9,4,IF(L7>=Правила!$B$10,3,2)))) | N7: =IF(OR(H7="нет СОЧ",M7="нет СОЧ"),"нет СОЧ",IF(AND(H7=5,M7=5),"Отличник",IF(MIN(H7,M7)>=4,"Хорошист",IF(AND(MIN(H7,M7)=3,MAX(H7,M7)>=4),"Резерв (одна «3»)",""))))
A8: 8А | B8: 5 | C8: ='8А СОР-СОЧ'!B8 | D8: =IFERROR(INDEX('8А Алгебра'!$Z:$Z,MATCH($C8,'8А Алгебра'!$B:$B,0))/10,"") | E8: =('8А СОР-СОЧ'!C8)/('8А СОР-СОЧ'!C$19) | F8: =IF('8А СОР-СОЧ'!E8="","",'8А СОР-СОЧ'!E8/'8А СОР-СОЧ'!E$19) | G8: =IF(OR(F8="",D8=""),"",D8*Правила!$B$4+E8*Правила!$B$5+F8*Правила!$B$6) | H8: =IF(G8="","нет СОЧ",IF(G8>=Правила!$B$8,5,IF(G8>=Правила!$B$9,4,IF(G8>=Правила!$B$10,3,2)))) | I8: =IFERROR(INDEX('8А Геометрия'!$S:$S,MATCH($C8,'8А Геометрия'!$B:$B,0))/10,"") | J8: =('8А СОР-СОЧ'!G8)/('8А СОР-СОЧ'!G$19) | K8: =IF('8А СОР-СОЧ'!I8="","",'8А СОР-СОЧ'!I8/'8А СОР-СОЧ'!I$19) | L8: =IF(OR(K8="",I8=""),"",I8*Правила!$B$4+J8*Правила!$B$5+K8*Правила!$B$6) | M8: =IF(L8="","нет СОЧ",IF(L8>=Правила!$B$8,5,IF(L8>=Правила!$B$9,4,IF(L8>=Правила!$B$10,3,2)))) | N8: =IF(OR(H8="нет СОЧ",M8="нет СОЧ"),"нет СОЧ",IF(AND(H8=5,M8=5),"Отличник",IF(MIN(H8,M8)>=4,"Хорошист",IF(AND(MIN(H8,M8)=3,MAX(H8,M8)>=4),"Резерв (одна «3»)",""))))
A9: 8А | B9: 6 | C9: ='8А СОР-СОЧ'!B9 | D9: =IFERROR(INDEX('8А Алгебра'!$Z:$Z,MATCH($C9,'8А Алгебра'!$B:$B,0))/10,"") | E9: =('8А СОР-СОЧ'!C9)/('8А СОР-СОЧ'!C$19) | F9: =IF('8А СОР-СОЧ'!E9="","",'8А СОР-СОЧ'!E9/'8А СОР-СОЧ'!E$19) | G9: =IF(OR(F9="",D9=""),"",D9*Правила!$B$4+E9*Правила!$B$5+F9*Правила!$B$6) | H9: =IF(G9="","нет СОЧ",IF(G9>=Правила!$B$8,5,IF(G9>=Правила!$B$9,4,IF(G9>=Правила!$B$10,3,2)))) | I9: =IFERROR(INDEX('8А Геометрия'!$S:$S,MATCH($C9,'8А Геометрия'!$B:$B,0))/10,"") | J9: =('8А СОР-СОЧ'!G9)/('8А СОР-СОЧ'!G$19) | K9: =IF('8А СОР-СОЧ'!I9="","",'8А СОР-СОЧ'!I9/'8А СОР-СОЧ'!I$19) | L9: =IF(OR(K9="",I9=""),"",I9*Правила!$B$4+J9*Правила!$B$5+K9*Правила!$B$6) | M9: =IF(L9="","нет СОЧ",IF(L9>=Правила!$B$8,5,IF(L9>=Правила!$B$9,4,IF(L9>=Правила!$B$10,3,2)))) | N9: =IF(OR(H9="нет СОЧ",M9="нет СОЧ"),"нет СОЧ",IF(AND(H9=5,M9=5),"Отличник",IF(MIN(H9,M9)>=4,"Хорошист",IF(AND(MIN(H9,M9)=3,MAX(H9,M9)>=4),"Резерв (одна «3»)",""))))
A10: 8А | B10: 7 | C10: ='8А СОР-СОЧ'!B10 | D10: =IFERROR(INDEX('8А Алгебра'!$Z:$Z,MATCH($C10,'8А Алгебра'!$B:$B,0))/10,"") | E10: =('8А СОР-СОЧ'!C10)/('8А СОР-СОЧ'!C$19) | F10: =IF('8А СОР-СОЧ'!E10="","",'8А СОР-СОЧ'!E10/'8А СОР-СОЧ'!E$19) | G10: =IF(OR(F10="",D10=""),"",D10*Правила!$B$4+E10*Правила!$B$5+F10*Правила!$B$6) | H10: =IF(G10="","нет СОЧ",IF(G10>=Правила!$B$8,5,IF(G10>=Правила!$B$9,4,IF(G10>=Правила!$B$10,3,2)))) | I10: =IFERROR(INDEX('8А Геометрия'!$S:$S,MATCH($C10,'8А Геометрия'!$B:$B,0))/10,"") | J10: =('8А СОР-СОЧ'!G10)/('8А СОР-СОЧ'!G$19) | K10: =IF('8А СОР-СОЧ'!I10="","",'8А СОР-СОЧ'!I10/'8А СОР-СОЧ'!I$19) | L10: =IF(OR(K10="",I10=""),"",I10*Правила!$B$4+J10*Правила!$B$5+K10*Правила!$B$6) | M10: =IF(L10="","нет СОЧ",IF(L10>=Правила!$B$8,5,IF(L10>=Правила!$B$9,4,IF(L10>=Правила!$B$10,3,2)))) | N10: =IF(OR(H10="нет СОЧ",M10="нет СОЧ"),"нет СОЧ",IF(AND(H10=5,M10=5),"Отличник",IF(MIN(H10,M10)>=4,"Хорошист",IF(AND(MIN(H10,M10)=3,MAX(H10,M10)>=4),"Резерв (одна «3»)",""))))
A11: 8А | B11: 8 | C11: ='8А СОР-СОЧ'!B11 | D11: =IFERROR(INDEX('8А Алгебра'!$Z:$Z,MATCH($C11,'8А Алгебра'!$B:$B,0))/10,"") | E11: =('8А СОР-СОЧ'!C11)/('8А СОР-СОЧ'!C$19) | F11: =IF('8А СОР-СОЧ'!E11="","",'8А СОР-СОЧ'!E11/'8А СОР-СОЧ'!E$19) | G11: =IF(OR(F11="",D11=""),"",D11*Правила!$B$4+E11*Правила!$B$5+F11*Правила!$B$6) | H11: =IF(G11="","нет СОЧ",IF(G11>=Правила!$B$8,5,IF(G11>=Правила!$B$9,4,IF(G11>=Правила!$B$10,3,2)))) | I11: =IFERROR(INDEX('8А Геометрия'!$S:$S,MATCH($C11,'8А Геометрия'!$B:$B,0))/10,"") | J11: =('8А СОР-СОЧ'!G11)/('8А СОР-СОЧ'!G$19) | K11: =IF('8А СОР-СОЧ'!I11="","",'8А СОР-СОЧ'!I11/'8А СОР-СОЧ'!I$19) | L11: =IF(OR(K11="",I11=""),"",I11*Правила!$B$4+J11*Правила!$B$5+K11*Правила!$B$6) | M11: =IF(L11="","нет СОЧ",IF(L11>=Правила!$B$8,5,IF(L11>=Правила!$B$9,4,IF(L11>=Правила!$B$10,3,2)))) | N11: =IF(OR(H11="нет СОЧ",M11="нет СОЧ"),"нет СОЧ",IF(AND(H11=5,M11=5),"Отличник",IF(MIN(H11,M11)>=4,"Хорошист",IF(AND(MIN(H11,M11)=3,MAX(H11,M11)>=4),"Резерв (одна «3»)",""))))
A12: 8А | B12: 9 | C12: ='8А СОР-СОЧ'!B12 | D12: =IFERROR(INDEX('8А Алгебра'!$Z:$Z,MATCH($C12,'8А Алгебра'!$B:$B,0))/10,"") | E12: =('8А СОР-СОЧ'!C12)/('8А СОР-СОЧ'!C$19) | F12: =IF('8А СОР-СОЧ'!E12="","",'8А СОР-СОЧ'!E12/'8А СОР-СОЧ'!E$19) | G12: =IF(OR(F12="",D12=""),"",D12*Правила!$B$4+E12*Правила!$B$5+F12*Правила!$B$6) | H12: =IF(G12="","нет СОЧ",IF(G12>=Правила!$B$8,5,IF(G12>=Правила!$B$9,4,IF(G12>=Правила!$B$10,3,2)))) | I12: =IFERROR(INDEX('8А Геометрия'!$S:$S,MATCH($C12,'8А Геометрия'!$B:$B,0))/10,"") | J12: =('8А СОР-СОЧ'!G12)/('8А СОР-СОЧ'!G$19) | K12: =IF('8А СОР-СОЧ'!I12="","",'8А СОР-СОЧ'!I12/'8А СОР-СОЧ'!I$19) | L12: =IF(OR(K12="",I12=""),"",I12*Правила!$B$4+J12*Правила!$B$5+K12*Правила!$B$6) | M12: =IF(L12="","нет СОЧ",IF(L12>=Правила!$B$8,5,IF(L12>=Правила!$B$9,4,IF(L12>=Правила!$B$10,3,2)))) | N12: =IF(OR(H12="нет СОЧ",M12="нет СОЧ"),"нет СОЧ",IF(AND(H12=5,M12=5),"Отличник",IF(MIN(H12,M12)>=4,"Хорошист",IF(AND(MIN(H12,M12)=3,MAX(H12,M12)>=4),"Резерв (одна «3»)",""))))
A13: 8А | B13: 10 | C13: ='8А СОР-СОЧ'!B13 | D13: =IFERROR(INDEX('8А Алгебра'!$Z:$Z,MATCH($C13,'8А Алгебра'!$B:$B,0))/10,"") | E13: =('8А СОР-СОЧ'!C13)/('8А СОР-СОЧ'!C$19) | F13: =IF('8А СОР-СОЧ'!E13="","",'8А СОР-СОЧ'!E13/'8А СОР-СОЧ'!E$19) | G13: =IF(OR(F13="",D13=""),"",D13*Правила!$B$4+E13*Правила!$B$5+F13*Правила!$B$6) | H13: =IF(G13="","нет СОЧ",IF(G13>=Правила!$B$8,5,IF(G13>=Правила!$B$9,4,IF(G13>=Правила!$B$10,3,2)))) | I13: =IFERROR(INDEX('8А Геометрия'!$S:$S,MATCH($C13,'8А Геометрия'!$B:$B,0))/10,"") | J13: =('8А СОР-СОЧ'!G13)/('8А СОР-СОЧ'!G$19) | K13: =IF('8А СОР-СОЧ'!I13="","",'8А СОР-СОЧ'!I13/'8А СОР-СОЧ'!I$19) | L13: =IF(OR(K13="",I13=""),"",I13*Правила!$B$4+J13*Правила!$B$5+K13*Правила!$B$6) | M13: =IF(L13="","нет СОЧ",IF(L13>=Правила!$B$8,5,IF(L13>=Правила!$B$9,4,IF(L13>=Правила!$B$10,3,2)))) | N13: =IF(OR(H13="нет СОЧ",M13="нет СОЧ"),"нет СОЧ",IF(AND(H13=5,M13=5),"Отличник",IF(MIN(H13,M13)>=4,"Хорошист",IF(AND(MIN(H13,M13)=3,MAX(H13,M13)>=4),"Резерв (одна «3»)",""))))
A14: 8А | B14: 11 | C14: ='8А СОР-СОЧ'!B14 | D14: =IFERROR(INDEX('8А Алгебра'!$Z:$Z,MATCH($C14,'8А Алгебра'!$B:$B,0))/10,"") | E14: =('8А СОР-СОЧ'!C14)/('8А СОР-СОЧ'!C$19) | F14: =IF('8А СОР-СОЧ'!E14="","",'8А СОР-СОЧ'!E14/'8А СОР-СОЧ'!E$19) | G14: =IF(OR(F14="",D14=""),"",D14*Правила!$B$4+E14*Правила!$B$5+F14*Правила!$B$6) | H14: =IF(G14="","нет СОЧ",IF(G14>=Правила!$B$8,5,IF(G14>=Правила!$B$9,4,IF(G14>=Правила!$B$10,3,2)))) | I14: =IFERROR(INDEX('8А Геометрия'!$S:$S,MATCH($C14,'8А Геометрия'!$B:$B,0))/10,"") | J14: =('8А СОР-СОЧ'!G14)/('8А СОР-СОЧ'!G$19) | K14: =IF('8А СОР-СОЧ'!I14="","",'8А СОР-СОЧ'!I14/'8А СОР-СОЧ'!I$19) | L14: =IF(OR(K14="",I14=""),"",I14*Правила!$B$4+J14*Правила!$B$5+K14*Правила!$B$6) | M14: =IF(L14="","нет СОЧ",IF(L14>=Правила!$B$8,5,IF(L14>=Правила!$B$9,4,IF(L14>=Правила!$B$10,3,2)))) | N14: =IF(OR(H14="нет СОЧ",M14="нет СОЧ"),"нет СОЧ",IF(AND(H14=5,M14=5),"Отличник",IF(MIN(H14,M14)>=4,"Хорошист",IF(AND(MIN(H14,M14)=3,MAX(H14,M14)>=4),"Резерв (одна «3»)",""))))
A15: 8А | B15: 12 | C15: ='8А СОР-СОЧ'!B15 | D15: =IFERROR(INDEX('8А Алгебра'!$Z:$Z,MATCH($C15,'8А Алгебра'!$B:$B,0))/10,"") | E15: =('8А СОР-СОЧ'!C15)/('8А СОР-СОЧ'!C$19) | F15: =IF('8А СОР-СОЧ'!E15="","",'8А СОР-СОЧ'!E15/'8А СОР-СОЧ'!E$19) | G15: =IF(OR(F15="",D15=""),"",D15*Правила!$B$4+E15*Правила!$B$5+F15*Правила!$B$6) | H15: =IF(G15="","нет СОЧ",IF(G15>=Правила!$B$8,5,IF(G15>=Правила!$B$9,4,IF(G15>=Правила!$B$10,3,2)))) | I15: =IFERROR(INDEX('8А Геометрия'!$S:$S,MATCH($C15,'8А Геометрия'!$B:$B,0))/10,"") | J15: =('8А СОР-СОЧ'!G15)/('8А СОР-СОЧ'!G$19) | K15: =IF('8А СОР-СОЧ'!I15="","",'8А СОР-СОЧ'!I15/'8А СОР-СОЧ'!I$19) | L15: =IF(OR(K15="",I15=""),"",I15*Правила!$B$4+J15*Правила!$B$5+K15*Правила!$B$6) | M15: =IF(L15="","нет СОЧ",IF(L15>=Правила!$B$8,5,IF(L15>=Правила!$B$9,4,IF(L15>=Правила!$B$10,3,2)))) | N15: =IF(OR(H15="нет СОЧ",M15="нет СОЧ"),"нет СОЧ",IF(AND(H15=5,M15=5),"Отличник",IF(MIN(H15,M15)>=4,"Хорошист",IF(AND(MIN(H15,M15)=3,MAX(H15,M15)>=4),"Резерв (одна «3»)",""))))
... A17: 8А | B17: 14 | C17: ='8А СОР-СОЧ'!B17 | D17: =IFERROR(INDEX('8А Алгебра'!$Z:$Z,MATCH($C17,'8А Алгебра'!$B:$B,0))/10,"") | E17: =('8А СОР-СОЧ'!C17)/('8А СОР-СОЧ'!C$19) | F17: =IF('8А СОР-СОЧ'!E17="","",'8А СОР-СОЧ'!E17/'8А СОР-СОЧ'!E$19) | G17: =IF(OR(F17="",D17=""),"",D17*Правила!$B$4+E17*Правила!$B$5+F17*Правила!$B$6) | H17: =IF(G17="","нет СОЧ",IF(G17>=Правила!$B$8,5,IF(G17>=Правила!$B$9,4,IF(G17>=Правила!$B$10,3,2)))) | I17: =IFERROR(INDEX('8А Геометрия'!$S:$S,MATCH($C17,'8А Геометрия'!$B:$B,0))/10,"") | J17: =('8А СОР-СОЧ'!G17)/('8А СОР-СОЧ'!G$19) | K17: =IF('8А СОР-СОЧ'!I17="","",'8А СОР-СОЧ'!I17/'8А СОР-СОЧ'!I$19) | L17: =IF(OR(K17="",I17=""),"",I17*Правила!$B$4+J17*Правила!$B$5+K17*Правила!$B$6) | M17: =IF(L17="","нет СОЧ",IF(L17>=Правила!$B$8,5,IF(L17>=Правила!$B$9,4,IF(L17>=Правила!$B$10,3,2)))) | N17: =IF(OR(H17="нет СОЧ",M17="нет СОЧ"),"нет СОЧ",IF(AND(H17=5,M17=5),"Отличник",IF(MIN(H17,M17)>=4,"Хорошист",IF(AND(MIN(H17,M17)=3,MAX(H17,M17)>=4),"Резерв (одна «3»)",""))))
A18: 8Б | B18: 1 | C18: ='8Б СОР-СОЧ'!B4 | D18: =IFERROR(INDEX('8Б Алгебра'!$Z:$Z,MATCH($C18,'8Б Алгебра'!$B:$B,0))/10,"") | E18: =('8Б СОР-СОЧ'!C4)/('8Б СОР-СОЧ'!C$18) | F18: =IF('8Б СОР-СОЧ'!E4="","",'8Б СОР-СОЧ'!E4/'8Б СОР-СОЧ'!E$18) | G18: =IF(OR(F18="",D18=""),"",D18*Правила!$B$4+E18*Правила!$B$5+F18*Правила!$B$6) | H18: =IF(G18="","нет СОЧ",IF(G18>=Правила!$B$8,5,IF(G18>=Правила!$B$9,4,IF(G18>=Правила!$B$10,3,2)))) | I18: =IFERROR(INDEX('8Б Геометрия'!$S:$S,MATCH($C18,'8Б Геометрия'!$B:$B,0))/10,"") | J18: =('8Б СОР-СОЧ'!G4)/('8Б СОР-СОЧ'!G$18) | K18: =IF('8Б СОР-СОЧ'!I4="","",'8Б СОР-СОЧ'!I4/'8Б СОР-СОЧ'!I$18) | L18: =IF(OR(K18="",I18=""),"",I18*Правила!$B$4+J18*Правила!$B$5+K18*Правила!$B$6) | M18: =IF(L18="","нет СОЧ",IF(L18>=Правила!$B$8,5,IF(L18>=Правила!$B$9,4,IF(L18>=Правила!$B$10,3,2)))) | N18: =IF(OR(H18="нет СОЧ",M18="нет СОЧ"),"нет СОЧ",IF(AND(H18=5,M18=5),"Отличник",IF(MIN(H18,M18)>=4,"Хорошист",IF(AND(MIN(H18,M18)=3,MAX(H18,M18)>=4),"Резерв (одна «3»)",""))))
A19: 8Б | B19: 2 | C19: ='8Б СОР-СОЧ'!B5 | D19: =IFERROR(INDEX('8Б Алгебра'!$Z:$Z,MATCH($C19,'8Б Алгебра'!$B:$B,0))/10,"") | E19: =('8Б СОР-СОЧ'!C5)/('8Б СОР-СОЧ'!C$18) | F19: =IF('8Б СОР-СОЧ'!E5="","",'8Б СОР-СОЧ'!E5/'8Б СОР-СОЧ'!E$18) | G19: =IF(OR(F19="",D19=""),"",D19*Правила!$B$4+E19*Правила!$B$5+F19*Правила!$B$6) | H19: =IF(G19="","нет СОЧ",IF(G19>=Правила!$B$8,5,IF(G19>=Правила!$B$9,4,IF(G19>=Правила!$B$10,3,2)))) | I19: =IFERROR(INDEX('8Б Геометрия'!$S:$S,MATCH($C19,'8Б Геометрия'!$B:$B,0))/10,"") | J19: =('8Б СОР-СОЧ'!G5)/('8Б СОР-СОЧ'!G$18) | K19: =IF('8Б СОР-СОЧ'!I5="","",'8Б СОР-СОЧ'!I5/'8Б СОР-СОЧ'!I$18) | L19: =IF(OR(K19="",I19=""),"",I19*Правила!$B$4+J19*Правила!$B$5+K19*Правила!$B$6) | M19: =IF(L19="","нет СОЧ",IF(L19>=Правила!$B$8,5,IF(L19>=Правила!$B$9,4,IF(L19>=Правила!$B$10,3,2)))) | N19: =IF(OR(H19="нет СОЧ",M19="нет СОЧ"),"нет СОЧ",IF(AND(H19=5,M19=5),"Отличник",IF(MIN(H19,M19)>=4,"Хорошист",IF(AND(MIN(H19,M19)=3,MAX(H19,M19)>=4),"Резерв (одна «3»)",""))))
A20: 8Б | B20: 3 | C20: ='8Б СОР-СОЧ'!B6 | D20: =IFERROR(INDEX('8Б Алгебра'!$Z:$Z,MATCH($C20,'8Б Алгебра'!$B:$B,0))/10,"") | E20: =('8Б СОР-СОЧ'!C6)/('8Б СОР-СОЧ'!C$18) | F20: =IF('8Б СОР-СОЧ'!E6="","",'8Б СОР-СОЧ'!E6/'8Б СОР-СОЧ'!E$18) | G20: =IF(OR(F20="",D20=""),"",D20*Правила!$B$4+E20*Правила!$B$5+F20*Правила!$B$6) | H20: =IF(G20="","нет СОЧ",IF(G20>=Правила!$B$8,5,IF(G20>=Правила!$B$9,4,IF(G20>=Правила!$B$10,3,2)))) | I20: =IFERROR(INDEX('8Б Геометрия'!$S:$S,MATCH($C20,'8Б Геометрия'!$B:$B,0))/10,"") | J20: =('8Б СОР-СОЧ'!G6)/('8Б СОР-СОЧ'!G$18) | K20: =IF('8Б СОР-СОЧ'!I6="","",'8Б СОР-СОЧ'!I6/'8Б СОР-СОЧ'!I$18) | L20: =IF(OR(K20="",I20=""),"",I20*Правила!$B$4+J20*Правила!$B$5+K20*Правила!$B$6) | M20: =IF(L20="","нет СОЧ",IF(L20>=Правила!$B$8,5,IF(L20>=Правила!$B$9,4,IF(L20>=Правила!$B$10,3,2)))) | N20: =IF(OR(H20="нет СОЧ",M20="нет СОЧ"),"нет СОЧ",IF(AND(H20=5,M20=5),"Отличник",IF(MIN(H20,M20)>=4,"Хорошист",IF(AND(MIN(H20,M20)=3,MAX(H20,M20)>=4),"Резерв (одна «3»)",""))))
A21: 8Б | B21: 4 | C21: ='8Б СОР-СОЧ'!B7 | D21: =IFERROR(INDEX('8Б Алгебра'!$Z:$Z,MATCH($C21,'8Б Алгебра'!$B:$B,0))/10,"") | E21: =('8Б СОР-СОЧ'!C7)/('8Б СОР-СОЧ'!C$18) | F21: =IF('8Б СОР-СОЧ'!E7="","",'8Б СОР-СОЧ'!E7/'8Б СОР-СОЧ'!E$18) | G21: =IF(OR(F21="",D21=""),"",D21*Правила!$B$4+E21*Правила!$B$5+F21*Правила!$B$6) | H21: =IF(G21="","нет СОЧ",IF(G21>=Правила!$B$8,5,IF(G21>=Правила!$B$9,4,IF(G21>=Правила!$B$10,3,2)))) | I21: =IFERROR(INDEX('8Б Геометрия'!$S:$S,MATCH($C21,'8Б Геометрия'!$B:$B,0))/10,"") | J21: =('8Б СОР-СОЧ'!G7)/('8Б СОР-СОЧ'!G$18) | K21: =IF('8Б СОР-СОЧ'!I7="","",'8Б СОР-СОЧ'!I7/'8Б СОР-СОЧ'!I$18) | L21: =IF(OR(K21="",I21=""),"",I21*Правила!$B$4+J21*Правила!$B$5+K21*Правила!$B$6) | M21: =IF(L21="","нет СОЧ",IF(L21>=Правила!$B$8,5,IF(L21>=Правила!$B$9,4,IF(L21>=Правила!$B$10,3,2)))) | N21: =IF(OR(H21="нет СОЧ",M21="нет СОЧ"),"нет СОЧ",IF(AND(H21=5,M21=5),"Отличник",IF(MIN(H21,M21)>=4,"Хорошист",IF(AND(MIN(H21,M21)=3,MAX(H21,M21)>=4),"Резерв (одна «3»)",""))))
A22: 8Б | B22: 5 | C22: ='8Б СОР-СОЧ'!B8 | D22: =IFERROR(INDEX('8Б Алгебра'!$Z:$Z,MATCH($C22,'8Б Алгебра'!$B:$B,0))/10,"") | E22: =('8Б СОР-СОЧ'!C8)/('8Б СОР-СОЧ'!C$18) | F22: =IF('8Б СОР-СОЧ'!E8="","",'8Б СОР-СОЧ'!E8/'8Б СОР-СОЧ'!E$18) | G22: =IF(OR(F22="",D22=""),"",D22*Правила!$B$4+E22*Правила!$B$5+F22*Правила!$B$6) | H22: =IF(G22="","нет СОЧ",IF(G22>=Правила!$B$8,5,IF(G22>=Правила!$B$9,4,IF(G22>=Правила!$B$10,3,2)))) | I22: =IFERROR(INDEX('8Б Геометрия'!$S:$S,MATCH($C22,'8Б Геометрия'!$B:$B,0))/10,"") | J22: =('8Б СОР-СОЧ'!G8)/('8Б СОР-СОЧ'!G$18) | K22: =IF('8Б СОР-СОЧ'!I8="","",'8Б СОР-СОЧ'!I8/'8Б СОР-СОЧ'!I$18) | L22: =IF(OR(K22="",I22=""),"",I22*Правила!$B$4+J22*Правила!$B$5+K22*Правила!$B$6) | M22: =IF(L22="","нет СОЧ",IF(L22>=Правила!$B$8,5,IF(L22>=Правила!$B$9,4,IF(L22>=Правила!$B$10,3,2)))) | N22: =IF(OR(H22="нет СОЧ",M22="нет СОЧ"),"нет СОЧ",IF(AND(H22=5,M22=5),"Отличник",IF(MIN(H22,M22)>=4,"Хорошист",IF(AND(MIN(H22,M22)=3,MAX(H22,M22)>=4),"Резерв (одна «3»)",""))))
A23: 8Б | B23: 6 | C23: ='8Б СОР-СОЧ'!B9 | D23: =IFERROR(INDEX('8Б Алгебра'!$Z:$Z,MATCH($C23,'8Б Алгебра'!$B:$B,0))/10,"") | E23: =('8Б СОР-СОЧ'!C9)/('8Б СОР-СОЧ'!C$18) | F23: =IF('8Б СОР-СОЧ'!E9="","",'8Б СОР-СОЧ'!E9/'8Б СОР-СОЧ'!E$18) | G23: =IF(OR(F23="",D23=""),"",D23*Правила!$B$4+E23*Правила!$B$5+F23*Правила!$B$6) | H23: =IF(G23="","нет СОЧ",IF(G23>=Правила!$B$8,5,IF(G23>=Правила!$B$9,4,IF(G23>=Правила!$B$10,3,2)))) | I23: =IFERROR(INDEX('8Б Геометрия'!$S:$S,MATCH($C23,'8Б Геометрия'!$B:$B,0))/10,"") | J23: =('8Б СОР-СОЧ'!G9)/('8Б СОР-СОЧ'!G$18) | K23: =IF('8Б СОР-СОЧ'!I9="","",'8Б СОР-СОЧ'!I9/'8Б СОР-СОЧ'!I$18) | L23: =IF(OR(K23="",I23=""),"",I23*Правила!$B$4+J23*Правила!$B$5+K23*Правила!$B$6) | M23: =IF(L23="","нет СОЧ",IF(L23>=Правила!$B$8,5,IF(L23>=Правила!$B$9,4,IF(L23>=Правила!$B$10,3,2)))) | N23: =IF(OR(H23="нет СОЧ",M23="нет СОЧ"),"нет СОЧ",IF(AND(H23=5,M23=5),"Отличник",IF(MIN(H23,M23)>=4,"Хорошист",IF(AND(MIN(H23,M23)=3,MAX(H23,M23)>=4),"Резерв (одна «3»)",""))))
A24: 8Б | B24: 7 | C24: ='8Б СОР-СОЧ'!B10 | D24: =IFERROR(INDEX('8Б Алгебра'!$Z:$Z,MATCH($C24,'8Б Алгебра'!$B:$B,0))/10,"") | E24: =('8Б СОР-СОЧ'!C10)/('8Б СОР-СОЧ'!C$18) | F24: =IF('8Б СОР-СОЧ'!E10="","",'8Б СОР-СОЧ'!E10/'8Б СОР-СОЧ'!E$18) | G24: =IF(OR(F24="",D24=""),"",D24*Правила!$B$4+E24*Правила!$B$5+F24*Правила!$B$6) | H24: =IF(G24="","нет СОЧ",IF(G24>=Правила!$B$8,5,IF(G24>=Правила!$B$9,4,IF(G24>=Правила!$B$10,3,2)))) | I24: =IFERROR(INDEX('8Б Геометрия'!$S:$S,MATCH($C24,'8Б Геометрия'!$B:$B,0))/10,"") | J24: =('8Б СОР-СОЧ'!G10)/('8Б СОР-СОЧ'!G$18) | K24: =IF('8Б СОР-СОЧ'!I10="","",'8Б СОР-СОЧ'!I10/'8Б СОР-СОЧ'!I$18) | L24: =IF(OR(K24="",I24=""),"",I24*Правила!$B$4+J24*Правила!$B$5+K24*Правила!$B$6) | M24: =IF(L24="","нет СОЧ",IF(L24>=Правила!$B$8,5,IF(L24>=Правила!$B$9,4,IF(L24>=Правила!$B$10,3,2)))) | N24: =IF(OR(H24="нет СОЧ",M24="нет СОЧ"),"нет СОЧ",IF(AND(H24=5,M24=5),"Отличник",IF(MIN(H24,M24)>=4,"Хорошист",IF(AND(MIN(H24,M24)=3,MAX(H24,M24)>=4),"Резерв (одна «3»)",""))))
A25: 8Б | B25: 8 | C25: ='8Б СОР-СОЧ'!B11 | D25: =IFERROR(INDEX('8Б Алгебра'!$Z:$Z,MATCH($C25,'8Б Алгебра'!$B:$B,0))/10,"") | E25: =('8Б СОР-СОЧ'!C11)/('8Б СОР-СОЧ'!C$18) | F25: =IF('8Б СОР-СОЧ'!E11="","",'8Б СОР-СОЧ'!E11/'8Б СОР-СОЧ'!E$18) | G25: =IF(OR(F25="",D25=""),"",D25*Правила!$B$4+E25*Правила!$B$5+F25*Правила!$B$6) | H25: =IF(G25="","нет СОЧ",IF(G25>=Правила!$B$8,5,IF(G25>=Правила!$B$9,4,IF(G25>=Правила!$B$10,3,2)))) | I25: =IFERROR(INDEX('8Б Геометрия'!$S:$S,MATCH($C25,'8Б Геометрия'!$B:$B,0))/10,"") | J25: =('8Б СОР-СОЧ'!G11)/('8Б СОР-СОЧ'!G$18) | K25: =IF('8Б СОР-СОЧ'!I11="","",'8Б СОР-СОЧ'!I11/'8Б СОР-СОЧ'!I$18) | L25: =IF(OR(K25="",I25=""),"",I25*Правила!$B$4+J25*Правила!$B$5+K25*Правила!$B$6) | M25: =IF(L25="","нет СОЧ",IF(L25>=Правила!$B$8,5,IF(L25>=Правила!$B$9,4,IF(L25>=Правила!$B$10,3,2)))) | N25: =IF(OR(H25="нет СОЧ",M25="нет СОЧ"),"нет СОЧ",IF(AND(H25=5,M25=5),"Отличник",IF(MIN(H25,M25)>=4,"Хорошист",IF(AND(MIN(H25,M25)=3,MAX(H25,M25)>=4),"Резерв (одна «3»)",""))))
A26: 8Б | B26: 9 | C26: ='8Б СОР-СОЧ'!B12 | D26: =IFERROR(INDEX('8Б Алгебра'!$Z:$Z,MATCH($C26,'8Б Алгебра'!$B:$B,0))/10,"") | E26: =('8Б СОР-СОЧ'!C12)/('8Б СОР-СОЧ'!C$18) | F26: =IF('8Б СОР-СОЧ'!E12="","",'8Б СОР-СОЧ'!E12/'8Б СОР-СОЧ'!E$18) | G26: =IF(OR(F26="",D26=""),"",D26*Правила!$B$4+E26*Правила!$B$5+F26*Правила!$B$6) | H26: =IF(G26="","нет СОЧ",IF(G26>=Правила!$B$8,5,IF(G26>=Правила!$B$9,4,IF(G26>=Правила!$B$10,3,2)))) | I26: =IFERROR(INDEX('8Б Геометрия'!$S:$S,MATCH($C26,'8Б Геометрия'!$B:$B,0))/10,"") | J26: =('8Б СОР-СОЧ'!G12)/('8Б СОР-СОЧ'!G$18) | K26: =IF('8Б СОР-СОЧ'!I12="","",'8Б СОР-СОЧ'!I12/'8Б СОР-СОЧ'!I$18) | L26: =IF(OR(K26="",I26=""),"",I26*Правила!$B$4+J26*Правила!$B$5+K26*Правила!$B$6) | M26: =IF(L26="","нет СОЧ",IF(L26>=Правила!$B$8,5,IF(L26>=Правила!$B$9,4,IF(L26>=Правила!$B$10,3,2)))) | N26: =IF(OR(H26="нет СОЧ",M26="нет СОЧ"),"нет СОЧ",IF(AND(H26=5,M26=5),"Отличник",IF(MIN(H26,M26)>=4,"Хорошист",IF(AND(MIN(H26,M26)=3,MAX(H26,M26)>=4),"Резерв (одна «3»)",""))))
A27: 8Б | B27: 10 | C27: ='8Б СОР-СОЧ'!B13 | D27: =IFERROR(INDEX('8Б Алгебра'!$Z:$Z,MATCH($C27,'8Б Алгебра'!$B:$B,0))/10,"") | E27: =('8Б СОР-СОЧ'!C13)/('8Б СОР-СОЧ'!C$18) | F27: =IF('8Б СОР-СОЧ'!E13="","",'8Б СОР-СОЧ'!E13/'8Б СОР-СОЧ'!E$18) | G27: =IF(OR(F27="",D27=""),"",D27*Правила!$B$4+E27*Правила!$B$5+F27*Правила!$B$6) | H27: =IF(G27="","нет СОЧ",IF(G27>=Правила!$B$8,5,IF(G27>=Правила!$B$9,4,IF(G27>=Правила!$B$10,3,2)))) | I27: =IFERROR(INDEX('8Б Геометрия'!$S:$S,MATCH($C27,'8Б Геометрия'!$B:$B,0))/10,"") | J27: =('8Б СОР-СОЧ'!G13)/('8Б СОР-СОЧ'!G$18) | K27: =IF('8Б СОР-СОЧ'!I13="","",'8Б СОР-СОЧ'!I13/'8Б СОР-СОЧ'!I$18) | L27: =IF(OR(K27="",I27=""),"",I27*Правила!$B$4+J27*Правила!$B$5+K27*Правила!$B$6) | M27: =IF(L27="","нет СОЧ",IF(L27>=Правила!$B$8,5,IF(L27>=Правила!$B$9,4,IF(L27>=Правила!$B$10,3,2)))) | N27: =IF(OR(H27="нет СОЧ",M27="нет СОЧ"),"нет СОЧ",IF(AND(H27=5,M27=5),"Отличник",IF(MIN(H27,M27)>=4,"Хорошист",IF(AND(MIN(H27,M27)=3,MAX(H27,M27)>=4),"Резерв (одна «3»)",""))))
A28: 8Б | B28: 11 | C28: ='8Б СОР-СОЧ'!B14 | D28: =IFERROR(INDEX('8Б Алгебра'!$Z:$Z,MATCH($C28,'8Б Алгебра'!$B:$B,0))/10,"") | E28: =('8Б СОР-СОЧ'!C14)/('8Б СОР-СОЧ'!C$18) | F28: =IF('8Б СОР-СОЧ'!E14="","",'8Б СОР-СОЧ'!E14/'8Б СОР-СОЧ'!E$18) | G28: =IF(OR(F28="",D28=""),"",D28*Правила!$B$4+E28*Правила!$B$5+F28*Правила!$B$6) | H28: =IF(G28="","нет СОЧ",IF(G28>=Правила!$B$8,5,IF(G28>=Правила!$B$9,4,IF(G28>=Правила!$B$10,3,2)))) | I28: =IFERROR(INDEX('8Б Геометрия'!$S:$S,MATCH($C28,'8Б Геометрия'!$B:$B,0))/10,"") | J28: =('8Б СОР-СОЧ'!G14)/('8Б СОР-СОЧ'!G$18) | K28: =IF('8Б СОР-СОЧ'!I14="","",'8Б СОР-СОЧ'!I14/'8Б СОР-СОЧ'!I$18) | L28: =IF(OR(K28="",I28=""),"",I28*Правила!$B$4+J28*Правила!$B$5+K28*Правила!$B$6) | M28: =IF(L28="","нет СОЧ",IF(L28>=Правила!$B$8,5,IF(L28>=Правила!$B$9,4,IF(L28>=Правила!$B$10,3,2)))) | N28: =IF(OR(H28="нет СОЧ",M28="нет СОЧ"),"нет СОЧ",IF(AND(H28=5,M28=5),"Отличник",IF(MIN(H28,M28)>=4,"Хорошист",IF(AND(MIN(H28,M28)=3,MAX(H28,M28)>=4),"Резерв (одна «3»)",""))))
A29: 8Б | B29: 12 | C29: ='8Б СОР-СОЧ'!B15 | D29: =IFERROR(INDEX('8Б Алгебра'!$Z:$Z,MATCH($C29,'8Б Алгебра'!$B:$B,0))/10,"") | E29: =('8Б СОР-СОЧ'!C15)/('8Б СОР-СОЧ'!C$18) | F29: =IF('8Б СОР-СОЧ'!E15="","",'8Б СОР-СОЧ'!E15/'8Б СОР-СОЧ'!E$18) | G29: =IF(OR(F29="",D29=""),"",D29*Правила!$B$4+E29*Правила!$B$5+F29*Правила!$B$6) | H29: =IF(G29="","нет СОЧ",IF(G29>=Правила!$B$8,5,IF(G29>=Правила!$B$9,4,IF(G29>=Правила!$B$10,3,2)))) | I29: =IFERROR(INDEX('8Б Геометрия'!$S:$S,MATCH($C29,'8Б Геометрия'!$B:$B,0))/10,"") | J29: =('8Б СОР-СОЧ'!G15)/('8Б СОР-СОЧ'!G$18) | K29: =IF('8Б СОР-СОЧ'!I15="","",'8Б СОР-СОЧ'!I15/'8Б СОР-СОЧ'!I$18) | L29: =IF(OR(K29="",I29=""),"",I29*Правила!$B$4+J29*Правила!$B$5+K29*Правила!$B$6) | M29: =IF(L29="","нет СОЧ",IF(L29>=Правила!$B$8,5,IF(L29>=Правила!$B$9,4,IF(L29>=Правила!$B$10,3,2)))) | N29: =IF(OR(H29="нет СОЧ",M29="нет СОЧ"),"нет СОЧ",IF(AND(H29=5,M29=5),"Отличник",IF(MIN(H29,M29)>=4,"Хорошист",IF(AND(MIN(H29,M29)=3,MAX(H29,M29)>=4),"Резерв (одна «3»)",""))))
A30: 8Б | B30: 13 | C30: ='8Б СОР-СОЧ'!B16 | D30: =IFERROR(INDEX('8Б Алгебра'!$Z:$Z,MATCH($C30,'8Б Алгебра'!$B:$B,0))/10,"") | E30: =('8Б СОР-СОЧ'!C16)/('8Б СОР-СОЧ'!C$18) | F30: =IF('8Б СОР-СОЧ'!E16="","",'8Б СОР-СОЧ'!E16/'8Б СОР-СОЧ'!E$18) | G30: =IF(OR(F30="",D30=""),"",D30*Правила!$B$4+E30*Правила!$B$5+F30*Правила!$B$6) | H30: =IF(G30="","нет СОЧ",IF(G30>=Правила!$B$8,5,IF(G30>=Правила!$B$9,4,IF(G30>=Правила!$B$10,3,2)))) | I30: =IFERROR(INDEX('8Б Геометрия'!$S:$S,MATCH($C30,'8Б Геометрия'!$B:$B,0))/10,"") | J30: =('8Б СОР-СОЧ'!G16)/('8Б СОР-СОЧ'!G$18) | K30: =IF('8Б СОР-СОЧ'!I16="","",'8Б СОР-СОЧ'!I16/'8Б СОР-СОЧ'!I$18) | L30: =IF(OR(K30="",I30=""),"",I30*Правила!$B$4+J30*Правила!$B$5+K30*Правила!$B$6) | M30: =IF(L30="","нет СОЧ",IF(L30>=Правила!$B$8,5,IF(L30>=Правила!$B$9,4,IF(L30>=Правила!$B$10,3,2)))) | N30: =IF(OR(H30="нет СОЧ",M30="нет СОЧ"),"нет СОЧ",IF(AND(H30=5,M30=5),"Отличник",IF(MIN(H30,M30)>=4,"Хорошист",IF(AND(MIN(H30,M30)=3,MAX(H30,M30)>=4),"Резерв (одна «3»)",""))))
A31: 9Б | B31: 1 | C31: ='9Б СОР-СОЧ'!B4 | D31: =IFERROR(INDEX('9Б Алгебра'!$Z:$Z,MATCH($C31,'9Б Алгебра'!$B:$B,0))/10,"") | E31: =('9Б СОР-СОЧ'!C4+'9Б СОР-СОЧ'!E4)/('9Б СОР-СОЧ'!C$25+'9Б СОР-СОЧ'!E$25) | F31: =IF('9Б СОР-СОЧ'!G4="","",'9Б СОР-СОЧ'!G4/'9Б СОР-СОЧ'!G$25) | G31: =IF(OR(F31="",D31=""),"",D31*Правила!$B$4+E31*Правила!$B$5+F31*Правила!$B$6) | H31: =IF(G31="","нет СОЧ",IF(G31>=Правила!$B$8,5,IF(G31>=Правила!$B$9,4,IF(G31>=Правила!$B$10,3,2)))) | I31: =IFERROR(INDEX('9Б Геометрия'!$S:$S,MATCH($C31,'9Б Геометрия'!$B:$B,0))/10,"") | J31: =('9Б СОР-СОЧ'!I4)/('9Б СОР-СОЧ'!I$25) | K31: =IF('9Б СОР-СОЧ'!K4="","",'9Б СОР-СОЧ'!K4/'9Б СОР-СОЧ'!K$25) | L31: =IF(OR(K31="",I31=""),"",I31*Правила!$B$4+J31*Правила!$B$5+K31*Правила!$B$6) | M31: =IF(L31="","нет СОЧ",IF(L31>=Правила!$B$8,5,IF(L31>=Правила!$B$9,4,IF(L31>=Правила!$B$10,3,2)))) | N31: =IF(OR(H31="нет СОЧ",M31="нет СОЧ"),"нет СОЧ",IF(AND(H31=5,M31=5),"Отличник",IF(MIN(H31,M31)>=4,"Хорошист",IF(AND(MIN(H31,M31)=3,MAX(H31,M31)>=4),"Резерв (одна «3»)",""))))
A32: 9Б | B32: 2 | C32: ='9Б СОР-СОЧ'!B5 | D32: =IFERROR(INDEX('9Б Алгебра'!$Z:$Z,MATCH($C32,'9Б Алгебра'!$B:$B,0))/10,"") | E32: =('9Б СОР-СОЧ'!C5+'9Б СОР-СОЧ'!E5)/('9Б СОР-СОЧ'!C$25+'9Б СОР-СОЧ'!E$25) | F32: =IF('9Б СОР-СОЧ'!G5="","",'9Б СОР-СОЧ'!G5/'9Б СОР-СОЧ'!G$25) | G32: =IF(OR(F32="",D32=""),"",D32*Правила!$B$4+E32*Правила!$B$5+F32*Правила!$B$6) | H32: =IF(G32="","нет СОЧ",IF(G32>=Правила!$B$8,5,IF(G32>=Правила!$B$9,4,IF(G32>=Правила!$B$10,3,2)))) | I32: =IFERROR(INDEX('9Б Геометрия'!$S:$S,MATCH($C32,'9Б Геометрия'!$B:$B,0))/10,"") | J32: =('9Б СОР-СОЧ'!I5)/('9Б СОР-СОЧ'!I$25) | K32: =IF('9Б СОР-СОЧ'!K5="","",'9Б СОР-СОЧ'!K5/'9Б СОР-СОЧ'!K$25) | L32: =IF(OR(K32="",I32=""),"",I32*Правила!$B$4+J32*Правила!$B$5+K32*Правила!$B$6) | M32: =IF(L32="","нет СОЧ",IF(L32>=Правила!$B$8,5,IF(L32>=Правила!$B$9,4,IF(L32>=Правила!$B$10,3,2)))) | N32: =IF(OR(H32="нет СОЧ",M32="нет СОЧ"),"нет СОЧ",IF(AND(H32=5,M32=5),"Отличник",IF(MIN(H32,M32)>=4,"Хорошист",IF(AND(MIN(H32,M32)=3,MAX(H32,M32)>=4),"Резерв (одна «3»)",""))))
A33: 9Б | B33: 3 | C33: ='9Б СОР-СОЧ'!B6 | D33: =IFERROR(INDEX('9Б Алгебра'!$Z:$Z,MATCH($C33,'9Б Алгебра'!$B:$B,0))/10,"") | E33: =('9Б СОР-СОЧ'!C6+'9Б СОР-СОЧ'!E6)/('9Б СОР-СОЧ'!C$25+'9Б СОР-СОЧ'!E$25) | F33: =IF('9Б СОР-СОЧ'!G6="","",'9Б СОР-СОЧ'!G6/'9Б СОР-СОЧ'!G$25) | G33: =IF(OR(F33="",D33=""),"",D33*Правила!$B$4+E33*Правила!$B$5+F33*Правила!$B$6) | H33: =IF(G33="","нет СОЧ",IF(G33>=Правила!$B$8,5,IF(G33>=Правила!$B$9,4,IF(G33>=Правила!$B$10,3,2)))) | I33: =IFERROR(INDEX('9Б Геометрия'!$S:$S,MATCH($C33,'9Б Геометрия'!$B:$B,0))/10,"") | J33: =('9Б СОР-СОЧ'!I6)/('9Б СОР-СОЧ'!I$25) | K33: =IF('9Б СОР-СОЧ'!K6="","",'9Б СОР-СОЧ'!K6/'9Б СОР-СОЧ'!K$25) | L33: =IF(OR(K33="",I33=""),"",I33*Правила!$B$4+J33*Правила!$B$5+K33*Правила!$B$6) | M33: =IF(L33="","нет СОЧ",IF(L33>=Правила!$B$8,5,IF(L33>=Правила!$B$9,4,IF(L33>=Правила!$B$10,3,2)))) | N33: =IF(OR(H33="нет СОЧ",M33="нет СОЧ"),"нет СОЧ",IF(AND(H33=5,M33=5),"Отличник",IF(MIN(H33,M33)>=4,"Хорошист",IF(AND(MIN(H33,M33)=3,MAX(H33,M33)>=4),"Резерв (одна «3»)",""))))
A34: 9Б | B34: 4 | C34: ='9Б СОР-СОЧ'!B7 | D34: =IFERROR(INDEX('9Б Алгебра'!$Z:$Z,MATCH($C34,'9Б Алгебра'!$B:$B,0))/10,"") | E34: =('9Б СОР-СОЧ'!C7+'9Б СОР-СОЧ'!E7)/('9Б СОР-СОЧ'!C$25+'9Б СОР-СОЧ'!E$25) | F34: =IF('9Б СОР-СОЧ'!G7="","",'9Б СОР-СОЧ'!G7/'9Б СОР-СОЧ'!G$25) | G34: =IF(OR(F34="",D34=""),"",D34*Правила!$B$4+E34*Правила!$B$5+F34*Правила!$B$6) | H34: =IF(G34="","нет СОЧ",IF(G34>=Правила!$B$8,5,IF(G34>=Правила!$B$9,4,IF(G34>=Правила!$B$10,3,2)))) | I34: =IFERROR(INDEX('9Б Геометрия'!$S:$S,MATCH($C34,'9Б Геометрия'!$B:$B,0))/10,"") | J34: =('9Б СОР-СОЧ'!I7)/('9Б СОР-СОЧ'!I$25) | K34: =IF('9Б СОР-СОЧ'!K7="","",'9Б СОР-СОЧ'!K7/'9Б СОР-СОЧ'!K$25) | L34: =IF(OR(K34="",I34=""),"",I34*Правила!$B$4+J34*Правила!$B$5+K34*Правила!$B$6) | M34: =IF(L34="","нет СОЧ",IF(L34>=Правила!$B$8,5,IF(L34>=Правила!$B$9,4,IF(L34>=Правила!$B$10,3,2)))) | N34: =IF(OR(H34="нет СОЧ",M34="нет СОЧ"),"нет СОЧ",IF(AND(H34=5,M34=5),"Отличник",IF(MIN(H34,M34)>=4,"Хорошист",IF(AND(MIN(H34,M34)=3,MAX(H34,M34)>=4),"Резерв (одна «3»)",""))))
A35: 9Б | B35: 5 | C35: ='9Б СОР-СОЧ'!B8 | D35: =IFERROR(INDEX('9Б Алгебра'!$Z:$Z,MATCH($C35,'9Б Алгебра'!$B:$B,0))/10,"") | E35: =('9Б СОР-СОЧ'!C8+'9Б СОР-СОЧ'!E8)/('9Б СОР-СОЧ'!C$25+'9Б СОР-СОЧ'!E$25) | F35: =IF('9Б СОР-СОЧ'!G8="","",'9Б СОР-СОЧ'!G8/'9Б СОР-СОЧ'!G$25) | G35: =IF(OR(F35="",D35=""),"",D35*Правила!$B$4+E35*Правила!$B$5+F35*Правила!$B$6) | H35: =IF(G35="","нет СОЧ",IF(G35>=Правила!$B$8,5,IF(G35>=Правила!$B$9,4,IF(G35>=Правила!$B$10,3,2)))) | I35: =IFERROR(INDEX('9Б Геометрия'!$S:$S,MATCH($C35,'9Б Геометрия'!$B:$B,0))/10,"") | J35: =('9Б СОР-СОЧ'!I8)/('9Б СОР-СОЧ'!I$25) | K35: =IF('9Б СОР-СОЧ'!K8="","",'9Б СОР-СОЧ'!K8/'9Б СОР-СОЧ'!K$25) | L35: =IF(OR(K35="",I35=""),"",I35*Правила!$B$4+J35*Правила!$B$5+K35*Правила!$B$6) | M35: =IF(L35="","нет СОЧ",IF(L35>=Правила!$B$8,5,IF(L35>=Правила!$B$9,4,IF(L35>=Правила!$B$10,3,2)))) | N35: =IF(OR(H35="нет СОЧ",M35="нет СОЧ"),"нет СОЧ",IF(AND(H35=5,M35=5),"Отличник",IF(MIN(H35,M35)>=4,"Хорошист",IF(AND(MIN(H35,M35)=3,MAX(H35,M35)>=4),"Резерв (одна «3»)",""))))
A36: 9Б | B36: 6 | C36: ='9Б СОР-СОЧ'!B9 | D36: =IFERROR(INDEX('9Б Алгебра'!$Z:$Z,MATCH($C36,'9Б Алгебра'!$B:$B,0))/10,"") | E36: =('9Б СОР-СОЧ'!C9+'9Б СОР-СОЧ'!E9)/('9Б СОР-СОЧ'!C$25+'9Б СОР-СОЧ'!E$25) | F36: =IF('9Б СОР-СОЧ'!G9="","",'9Б СОР-СОЧ'!G9/'9Б СОР-СОЧ'!G$25) | G36: =IF(OR(F36="",D36=""),"",D36*Правила!$B$4+E36*Правила!$B$5+F36*Правила!$B$6) | H36: =IF(G36="","нет СОЧ",IF(G36>=Правила!$B$8,5,IF(G36>=Правила!$B$9,4,IF(G36>=Правила!$B$10,3,2)))) | I36: =IFERROR(INDEX('9Б Геометрия'!$S:$S,MATCH($C36,'9Б Геометрия'!$B:$B,0))/10,"") | J36: =('9Б СОР-СОЧ'!I9)/('9Б СОР-СОЧ'!I$25) | K36: =IF('9Б СОР-СОЧ'!K9="","",'9Б СОР-СОЧ'!K9/'9Б СОР-СОЧ'!K$25) | L36: =IF(OR(K36="",I36=""),"",I36*Правила!$B$4+J36*Правила!$B$5+K36*Правила!$B$6) | M36: =IF(L36="","нет СОЧ",IF(L36>=Правила!$B$8,5,IF(L36>=Правила!$B$9,4,IF(L36>=Правила!$B$10,3,2)))) | N36: =IF(OR(H36="нет СОЧ",M36="нет СОЧ"),"нет СОЧ",IF(AND(H36=5,M36=5),"Отличник",IF(MIN(H36,M36)>=4,"Хорошист",IF(AND(MIN(H36,M36)=3,MAX(H36,M36)>=4),"Резерв (одна «3»)",""))))
A37: 9Б | B37: 7 | C37: ='9Б СОР-СОЧ'!B10 | D37: =IFERROR(INDEX('9Б Алгебра'!$Z:$Z,MATCH($C37,'9Б Алгебра'!$B:$B,0))/10,"") | E37: =('9Б СОР-СОЧ'!C10+'9Б СОР-СОЧ'!E10)/('9Б СОР-СОЧ'!C$25+'9Б СОР-СОЧ'!E$25) | F37: =IF('9Б СОР-СОЧ'!G10="","",'9Б СОР-СОЧ'!G10/'9Б СОР-СОЧ'!G$25) | G37: =IF(OR(F37="",D37=""),"",D37*Правила!$B$4+E37*Правила!$B$5+F37*Правила!$B$6) | H37: =IF(G37="","нет СОЧ",IF(G37>=Правила!$B$8,5,IF(G37>=Правила!$B$9,4,IF(G37>=Правила!$B$10,3,2)))) | I37: =IFERROR(INDEX('9Б Геометрия'!$S:$S,MATCH($C37,'9Б Геометрия'!$B:$B,0))/10,"") | J37: =('9Б СОР-СОЧ'!I10)/('9Б СОР-СОЧ'!I$25) | K37: =IF('9Б СОР-СОЧ'!K10="","",'9Б СОР-СОЧ'!K10/'9Б СОР-СОЧ'!K$25) | L37: =IF(OR(K37="",I37=""),"",I37*Правила!$B$4+J37*Правила!$B$5+K37*Правила!$B$6) | M37: =IF(L37="","нет СОЧ",IF(L37>=Правила!$B$8,5,IF(L37>=Правила!$B$9,4,IF(L37>=Правила!$B$10,3,2)))) | N37: =IF(OR(H37="нет СОЧ",M37="нет СОЧ"),"нет СОЧ",IF(AND(H37=5,M37=5),"Отличник",IF(MIN(H37,M37)>=4,"Хорошист",IF(AND(MIN(H37,M37)=3,MAX(H37,M37)>=4),"Резерв (одна «3»)",""))))
A38: 9Б | B38: 8 | C38: ='9Б СОР-СОЧ'!B11 | D38: =IFERROR(INDEX('9Б Алгебра'!$Z:$Z,MATCH($C38,'9Б Алгебра'!$B:$B,0))/10,"") | E38: =('9Б СОР-СОЧ'!C11+'9Б СОР-СОЧ'!E11)/('9Б СОР-СОЧ'!C$25+'9Б СОР-СОЧ'!E$25) | F38: =IF('9Б СОР-СОЧ'!G11="","",'9Б СОР-СОЧ'!G11/'9Б СОР-СОЧ'!G$25) | G38: =IF(OR(F38="",D38=""),"",D38*Правила!$B$4+E38*Правила!$B$5+F38*Правила!$B$6) | H38: =IF(G38="","нет СОЧ",IF(G38>=Правила!$B$8,5,IF(G38>=Правила!$B$9,4,IF(G38>=Правила!$B$10,3,2)))) | I38: =IFERROR(INDEX('9Б Геометрия'!$S:$S,MATCH($C38,'9Б Геометрия'!$B:$B,0))/10,"") | J38: =('9Б СОР-СОЧ'!I11)/('9Б СОР-СОЧ'!I$25) | K38: =IF('9Б СОР-СОЧ'!K11="","",'9Б СОР-СОЧ'!K11/'9Б СОР-СОЧ'!K$25) | L38: =IF(OR(K38="",I38=""),"",I38*Правила!$B$4+J38*Правила!$B$5+K38*Правила!$B$6) | M38: =IF(L38="","нет СОЧ",IF(L38>=Правила!$B$8,5,IF(L38>=Правила!$B$9,4,IF(L38>=Правила!$B$10,3,2)))) | N38: =IF(OR(H38="нет СОЧ",M38="нет СОЧ"),"нет СОЧ",IF(AND(H38=5,M38=5),"Отличник",IF(MIN(H38,M38)>=4,"Хорошист",IF(AND(MIN(H38,M38)=3,MAX(H38,M38)>=4),"Резерв (одна «3»)",""))))
A39: 9Б | B39: 9 | C39: ='9Б СОР-СОЧ'!B12 | D39: =IFERROR(INDEX('9Б Алгебра'!$Z:$Z,MATCH($C39,'9Б Алгебра'!$B:$B,0))/10,"") | E39: =('9Б СОР-СОЧ'!C12+'9Б СОР-СОЧ'!E12)/('9Б СОР-СОЧ'!C$25+'9Б СОР-СОЧ'!E$25) | F39: =IF('9Б СОР-СОЧ'!G12="","",'9Б СОР-СОЧ'!G12/'9Б СОР-СОЧ'!G$25) | G39: =IF(OR(F39="",D39=""),"",D39*Правила!$B$4+E39*Правила!$B$5+F39*Правила!$B$6) | H39: =IF(G39="","нет СОЧ",IF(G39>=Правила!$B$8,5,IF(G39>=Правила!$B$9,4,IF(G39>=Правила!$B$10,3,2)))) | I39: =IFERROR(INDEX('9Б Геометрия'!$S:$S,MATCH($C39,'9Б Геометрия'!$B:$B,0))/10,"") | J39: =('9Б СОР-СОЧ'!I12)/('9Б СОР-СОЧ'!I$25) | K39: =IF('9Б СОР-СОЧ'!K12="","",'9Б СОР-СОЧ'!K12/'9Б СОР-СОЧ'!K$25) | L39: =IF(OR(K39="",I39=""),"",I39*Правила!$B$4+J39*Правила!$B$5+K39*Правила!$B$6) | M39: =IF(L39="","нет СОЧ",IF(L39>=Правила!$B$8,5,IF(L39>=Правила!$B$9,4,IF(L39>=Правила!$B$10,3,2)))) | N39: =IF(OR(H39="нет СОЧ",M39="нет СОЧ"),"нет СОЧ",IF(AND(H39=5,M39=5),"Отличник",IF(MIN(H39,M39)>=4,"Хорошист",IF(AND(MIN(H39,M39)=3,MAX(H39,M39)>=4),"Резерв (одна «3»)",""))))
A40: 9Б | B40: 10 | C40: ='9Б СОР-СОЧ'!B13 | D40: =IFERROR(INDEX('9Б Алгебра'!$Z:$Z,MATCH($C40,'9Б Алгебра'!$B:$B,0))/10,"") | E40: =('9Б СОР-СОЧ'!C13+'9Б СОР-СОЧ'!E13)/('9Б СОР-СОЧ'!C$25+'9Б СОР-СОЧ'!E$25) | F40: =IF('9Б СОР-СОЧ'!G13="","",'9Б СОР-СОЧ'!G13/'9Б СОР-СОЧ'!G$25) | G40: =IF(OR(F40="",D40=""),"",D40*Правила!$B$4+E40*Правила!$B$5+F40*Правила!$B$6) | H40: =IF(G40="","нет СОЧ",IF(G40>=Правила!$B$8,5,IF(G40>=Правила!$B$9,4,IF(G40>=Правила!$B$10,3,2)))) | I40: =IFERROR(INDEX('9Б Геометрия'!$S:$S,MATCH($C40,'9Б Геометрия'!$B:$B,0))/10,"") | J40: =('9Б СОР-СОЧ'!I13)/('9Б СОР-СОЧ'!I$25) | K40: =IF('9Б СОР-СОЧ'!K13="","",'9Б СОР-СОЧ'!K13/'9Б СОР-СОЧ'!K$25) | L40: =IF(OR(K40="",I40=""),"",I40*Правила!$B$4+J40*Правила!$B$5+K40*Правила!$B$6) | M40: =IF(L40="","нет СОЧ",IF(L40>=Правила!$B$8,5,IF(L40>=Правила!$B$9,4,IF(L40>=Правила!$B$10,3,2)))) | N40: =IF(OR(H40="нет СОЧ",M40="нет СОЧ"),"нет СОЧ",IF(AND(H40=5,M40=5),"Отличник",IF(MIN(H40,M40)>=4,"Хорошист",IF(AND(MIN(H40,M40)=3,MAX(H40,M40)>=4),"Резерв (одна «3»)",""))))
A41: 9Б | B41: 11 | C41: ='9Б СОР-СОЧ'!B14 | D41: =IFERROR(INDEX('9Б Алгебра'!$Z:$Z,MATCH($C41,'9Б Алгебра'!$B:$B,0))/10,"") | E41: =('9Б СОР-СОЧ'!C14+'9Б СОР-СОЧ'!E14)/('9Б СОР-СОЧ'!C$25+'9Б СОР-СОЧ'!E$25) | F41: =IF('9Б СОР-СОЧ'!G14="","",'9Б СОР-СОЧ'!G14/'9Б СОР-СОЧ'!G$25) | G41: =IF(OR(F41="",D41=""),"",D41*Правила!$B$4+E41*Правила!$B$5+F41*Правила!$B$6) | H41: =IF(G41="","нет СОЧ",IF(G41>=Правила!$B$8,5,IF(G41>=Правила!$B$9,4,IF(G41>=Правила!$B$10,3,2)))) | I41: =IFERROR(INDEX('9Б Геометрия'!$S:$S,MATCH($C41,'9Б Геометрия'!$B:$B,0))/10,"") | J41: =('9Б СОР-СОЧ'!I14)/('9Б СОР-СОЧ'!I$25) | K41: =IF('9Б СОР-СОЧ'!K14="","",'9Б СОР-СОЧ'!K14/'9Б СОР-СОЧ'!K$25) | L41: =IF(OR(K41="",I41=""),"",I41*Правила!$B$4+J41*Правила!$B$5+K41*Правила!$B$6) | M41: =IF(L41="","нет СОЧ",IF(L41>=Правила!$B$8,5,IF(L41>=Правила!$B$9,4,IF(L41>=Правила!$B$10,3,2)))) | N41: =IF(OR(H41="нет СОЧ",M41="нет СОЧ"),"нет СОЧ",IF(AND(H41=5,M41=5),"Отличник",IF(MIN(H41,M41)>=4,"Хорошист",IF(AND(MIN(H41,M41)=3,MAX(H41,M41)>=4),"Резерв (одна «3»)",""))))
...

Sheet Отличники и хорошисты
A1: Отличники и хорошисты по математике — 1 четверть 2026/2027
A3: Сводка по классам
A4: Класс | B4: Учеников | C4: Отличники | D4: Хорошисты | E4: Резерв (одна «3») | F4: Нет СОЧ | G4: Качество знаний | H4: Успеваемость
A5: 8А | B5: =COUNTIF(Четвертные!$A:$A,A5) | C5: =COUNTIFS(Четвертные!$A:$A,$A5,Четвертные!$N:$N,"Отличник") | D5: =COUNTIFS(Четвертные!$A:$A,$A5,Четвертные!$N:$N,"Хорошист") | E5: =COUNTIFS(Четвертные!$A:$A,$A5,Четвертные!$N:$N,"Резерв (одна «3»)") | F5: =COUNTIFS(Четвертные!$A:$A,$A5,Четвертные!$N:$N,"нет СОЧ") | G5: =(C5+D5)/B5 | H5: =1-(SUMPRODUCT((Четвертные!$A$4:$A$100=$A5)*(((Четвертные!$H$4:$H$100=2)+(Четвертные!$M$4:$M$100=2))>0)))/B5
A6: 8Б | B6: =COUNTIF(Четвертные!$A:$A,A6) | C6: =COUNTIFS(Четвертные!$A:$A,$A6,Четвертные!$N:$N,"Отличник") | D6: =COUNTIFS(Четвертные!$A:$A,$A6,Четвертные!$N:$N,"Хорошист") | E6: =COUNTIFS(Четвертные!$A:$A,$A6,Четвертные!$N:$N,"Резерв (одна «3»)") | F6: =COUNTIFS(Четвертные!$A:$A,$A6,Четвертные!$N:$N,"нет СОЧ") | G6: =(C6+D6)/B6 | H6: =1-(SUMPRODUCT((Четвертные!$A$4:$A$100=$A6)*(((Четвертные!$H$4:$H$100=2)+(Четвертные!$M$4:$M$100=2))>0)))/B6
A7: 9Б | B7: =COUNTIF(Четвертные!$A:$A,A7) | C7: =COUNTIFS(Четвертные!$A:$A,$A7,Четвертные!$N:$N,"Отличник") | D7: =COUNTIFS(Четвертные!$A:$A,$A7,Четвертные!$N:$N,"Хорошист") | E7: =COUNTIFS(Четвертные!$A:$A,$A7,Четвертные!$N:$N,"Резерв (одна «3»)") | F7: =COUNTIFS(Четвертные!$A:$A,$A7,Четвертные!$N:$N,"нет СОЧ") | G7: =(C7+D7)/B7 | H7: =1-(SUMPRODUCT((Четвертные!$A$4:$A$100=$A7)*(((Четвертные!$H$4:$H$100=2)+(Четвертные!$M$4:$M$100=2))>0)))/B7
A8: 10А | B8: =COUNTIF(Четвертные!$A:$A,A8) | C8: =COUNTIFS(Четвертные!$A:$A,$A8,Четвертные!$N:$N,"Отличник") | D8: =COUNTIFS(Четвертные!$A:$A,$A8,Четвертные!$N:$N,"Хорошист") | E8: =COUNTIFS(Четвертные!$A:$A,$A8,Четвертные!$N:$N,"Резерв (одна «3»)") | F8: =COUNTIFS(Четвертные!$A:$A,$A8,Четвертные!$N:$N,"нет СОЧ") | G8: =(C8+D8)/B8 | H8: =1-(SUMPRODUCT((Четвертные!$A$4:$A$100=$A8)*(((Четвертные!$H$4:$H$100=2)+(Четвертные!$M$4:$M$100=2))>0)))/B8
A9: Всего | B9: =SUM(B5:B8) | C9: =SUM(C5:C8) | D9: =SUM(D5:D8) | E9: =SUM(E5:E8) | F9: =SUM(F5:F8) | G9: =(C9+D9)/B9 | H9: =SUMPRODUCT(H5:H8,B5:B8)/B9
A10: Качество знаний = (отличники + хорошисты) ÷ все ученики. Успеваемость = доля учеников без «2».
A12: 8А класс
A13: Отличники: 3
A14: № | B14: ФИО | C14: Алгебра | D14: Итог % алг. | E14: Геометрия | F14: Итог % геом.
A15: 1 | B15: =Четвертные!C13 | C15: =Четвертные!H13 | D15: =Четвертные!G13 | E15: =Четвертные!M13 | F15: =Четвертные!L13
A16: 2 | B16: =Четвертные!C14 | C16: =Четвертные!H14 | D16: =Четвертные!G14 | E16: =Четвертные!M14 | F16: =Четвертные!L14
A17: 3 | B17: =Четвертные!C17 | C17: =Четвертные!H17 | D17: =Четвертные!G17 | E17: =Четвертные!M17 | F17: =Четвертные!L17
A19: Хорошисты: 8
A20: № | B20: ФИО | C20: Алгебра | D20: Итог % алг. | E20: Геометрия | F20: Итог % геом.
A21: 1 | B21: =Четвертные!C4 | C21: =Четвертные!H4 | D21: =Четвертные!G4 | E21: =Четвертные!M4 | F21: =Четвертные!L4
A22: 2 | B22: =Четвертные!C5 | C22: =Четвертные!H5 | D22: =Четвертные!G5 | E22: =Четвертные!M5 | F22: =Четвертные!L5
A23: 3 | B23: =Четвертные!C6 | C23: =Четвертные!H6 | D23: =Четвертные!G6 | E23: =Четвертные!M6 | F23: =Четвертные!L6
A24: 4 | B24: =Четвертные!C7 | C24: =Четвертные!H7 | D24: =Четвертные!G7 | E24: =Четвертные!M7 | F24: =Четвертные!L7
A25: 5 | B25: =Четвертные!C8 | C25: =Четвертные!H8 | D25: =Четвертные!G8 | E25: =Четвертные!M8 | F25: =Четвертные!L8
A26: 6 | B26: =Четвертные!C11 | C26: =Четвертные!H11 | D26: =Четвертные!G11 | E26: =Четвертные!M11 | F26: =Четвертные!L11
A27: 7 | B27: =Четвертные!C12 | C27: =Четвертные!H12 | D27: =Четвертные!G12 | E27: =Четвертные!M12 | F27: =Четвертные!L12
A28: 8 | B28: =Четвертные!C15 | C28: =Четвертные!H15 | D28: =Четвертные!G15 | E28: =Четвертные!M15 | F28: =Четвертные!L15
A31: 8Б класс
A32: Отличники: 1
A33: № | B33: ФИО | C33: Алгебра | D33: Итог % алг. | E33: Геометрия | F33: Итог % геом.
A34: 1 | B34: =Четвертные!C26 | C34: =Четвертные!H26 | D34: =Четвертные!G26 | E34: =Четвертные!M26 | F34: =Четвертные!L26
A36: Хорошисты: 7
A37: № | B37: ФИО | C37: Алгебра | D37: Итог % алг. | E37: Геометрия | F37: Итог % геом.
A38: 1 | B38: =Четвертные!C19 | C38: =Четвертные!H19 | D38: =Четвертные!G19 | E38: =Четвертные!M19 | F38: =Четвертные!L19
A39: 2 | B39: =Четвертные!C20 | C39: =Четвертные!H20 | D39: =Четвертные!G20 | E39: =Четвертные!M20 | F39: =Четвертные!L20
A40: 3 | B40: =Четвертные!C23 | C40: =Четвертные!H23 | D40: =Четвертные!G23 | E40: =Четвертные!M23 | F40: =Четвертные!L23
A41: 4 | B41: =Четвертные!C24 | C41: =Четвертные!H24 | D41: =Четвертные!G24 | E41: =Четвертные!M24 | F41: =Четвертные!L24
A42: 5 | B42: =Четвертные!C25 | C42: =Четвертные!H25 | D42: =Четвертные!G25 | E42: =Четвертные!M25 | F42: =Четвертные!L25
A43: 6 | B43: =Четвертные!C27 | C43: =Четвертные!H27 | D43: =Четвертные!G27 | E43: =Четвертные!M27 | F43: =Четвертные!L27
A44: 7 | B44: =Четвертные!C22 | C44: =Четвертные!H22 | D44: =Четвертные!G22 | E44: =Четвертные!M22 | F44: =Четвертные!L22
A45: Резерв — одна «3» (можно подтянуть до хорошистов): 0
A46: № | B46: ФИО | C46: Алгебра | D46: Итог % алг. | E46: Геометрия | F46: Итог % геом.
...

Sheet Сводка
A1: Сводка оценок — 1 четверть 2026/2027 (на 20.10.2026)
A2: Класс | B2: Ученик | C2: Алгебра (средний) | D2: Оценок по алгебре | E2: Геометрия (средний) | F2: Оценок по геометрии | G2: Общий средний | H2: Всего оценок
A3: 8А | B3: Абельдинова Жасмин | C3: 7.7 | D3: 14 | E3: 8.2 | F3: 10 | G3: 7.9 | H3: 24
A4: 8А | B4: БЕРДНИКОВА ЕВГЕНИЯ | C4: 8.3 | D4: 18 | E4: 7.8 | F4: 11 | G4: 8.1 | H4: 29
A5: 8А | B5: БЕРДНИКОВА ДАРЬЯ | C5: 7.2 | D5: 13 | E5: 7.5 | F5: 11 | G5: 7.4 | H5: 24
A6: 8А | B6: БУЧКОВА МИЛАНА | C6: 8.8 | D6: 14 | E6: 8.1 | F6: 11 | G6: 8.5 | H6: 25
A7: 8А | B7: ВАСИЛЬКОВСКИЙ ДАНИЛ | C7: 7 | D7: 17 | E7: 7.8 | F7: 11 | G7: 7.3 | H7: 28
A8: 8А | B8: ГАЛИПАД ДАНИЛ | C8: 5.2 | D8: 15 | E8: 5.7 | F8: 10 | G8: 5.4 | H8: 25
A9: 8А | B9: КИСМЕТЬЕВ ИСЛАМ | C9: 6.2 | D9: 13 | E9: 6 | F9: 9 | G9: 6.1 | H9: 22
A10: 8А | B10: КОХ КОНДРАТ | C10: 7.5 | D10: 16 | E10: 8.4 | F10: 11 | G10: 7.9 | H10: 27
A11: 8А | B11: КУЗНЕЦОВ РОМАН | C11: 6.6 | D11: 15 | E11: 6.8 | F11: 11 | G11: 6.7 | H11: 26
A12: 8А | B12: ПАЗНИКОВА ДАНАЯ | C12: 9.3 | D12: 19 | E12: 9.8 | F12: 13 | G12: 9.5 | H12: 32
A13: 8А | B13: ПОДОЛЬСКИЙ АРТЁМ | C13: 8.8 | D13: 17 | E13: 9.4 | F13: 12 | G13: 9.1 | H13: 29
A14: 8А | B14: РАМЕНСКАЯ ВЕРОНИКА | C14: 7.9 | D14: 17 | E14: 8.4 | F14: 11 | G14: 8.1 | H14: 28
... A61: 10А | B61: ТУРГУМБАЕВ САМИР | C61: 8 | D61: 16 | E61: 8.1 | F61: 10 | G61: 8 | H61: 26

Sheet 8А Алгебра
A1: 8А Алгебра — оценки (на 23.10.2026)
A2: № | B2: ФИО | C2: 02.09.26 | D2: 04.09.26 | E2: 07.09.26 | F2: 09.09.26 | G2: 11.09.26 | H2: 14.09.26 | I2: 16.09.26 | J2: 18.09.26 | K2: 21.09.26 | L2: 23.09.26 | M2: 25.09.26 | N2: 28.09.26 | O2: 30.09.26 | P2: 02.10.26 | Q2: 05.10.26 | R2: 07.10.26 | S2: 09.10.26 | T2: 12.10.26 СОР | U2: 14.10.26 | V2: 16.10.26 СОЧ | W2: 19.10.26 | X2: 21.10.26 | Y2: 23.10.26 | Z2: Средний
A3: 1 | B3: Абельдинова Жасмин | C3: 6 | D3: 8 | E3: 9 | F3: 8 | G3: 8 | H3: 7 | J3: 5 | K3: 9 | L3: 8 | N3: 8 | O3: 9 | P3: 9 | Q3: 4 | R3: 10 | U3: 8 | W3: 8 | X3: 8 | Y3: 8 | Z3: =IFERROR(ROUND(AVERAGE(C3:Y3),1),"")
A4: 2 | B4: БЕРДНИКОВА ЕВГЕНИЯ | C4: 10 | D4: 9 | E4: 6 | F4: 9 | G4: 7 | H4: 7 | I4: 9 | J4: 9 | K4: 9 | L4: 6 | M4: 9 | N4: 10 | O4: 7 | P4: 9 | Q4: 6 | R4: 10 | S4: 9 | T4: 8 | U4: 8 | W4: 8 | X4: 8 | Z4: =IFERROR(ROUND(AVERAGE(C4:Y4),1),"")
A5: 3 | B5: БЕРДНИКОВА ДАРЬЯ | C5: 9 | E5: 7 | F5: 5 | G5: 7 | H5: 7 | J5: 6 | K5: 7 | L5: 7 | M5: 8 | O5: 7 | P5: 8 | Q5: 6 | R5: 10 | U5: 8 | X5: 8 | Z5: =IFERROR(ROUND(AVERAGE(C5:Y5),1),"")
A6: 4 | B6: БУЧКОВА МИЛАНА | C6: 9 | E6: 9 | F6: 9 | G6: 9 | H6: 9 | I6: 9 | J6: 9 | L6: 9 | M6: 9 | N6: 9 | O6: 9 | P6: 8 | Q6: 6 | R6: 10 | U6: 9 | W6: 10 | X6: 9 | Y6: 9 | Z6: =IFERROR(ROUND(AVERAGE(C6:Y6),1),"")
A7: 5 | B7: ВАСИЛЬКОВСКИЙ ДАНИЛ | C7: 9 | D7: 7 | E7: 7 | F7: 4 | G7: 7 | H7: 8 | I7: 6 | J7: 8 | K7: 7 | L7: 7 | M7: 6 | N7: 7 | O7: 7 | P7: 7 | Q7: 7 | R7: 10 | T7: 5 | X7: 8 | Y7: 8 | Z7: =IFERROR(ROUND(AVERAGE(C7:Y7),1),"")
A8: 6 | B8: ГАЛИПАД ДАНИЛ | C8: 5 | D8: 5 | E8: 5 | F8: 5 | G8: 6 | H8: 5 | I8: 5 | J8: 6 | K8: 5 | L8: 5 | M8: 5 | N8: 5 | O8: 5 | P8: 5 | S8: 6 | W8: 6 | Y8: 5 | Z8: =IFERROR(ROUND(AVERAGE(C8:Y8),1),"")
A9: 7 | B9: КИСМЕТЬЕВ ИСЛАМ | C9: 6 | D9: 6 | E9: 6 | G9: 6 | I9: 6 | J9: 6 | K9: 7 | L9: 6 | M9: 6 | N9: 8 | O9: 6 | P9: 6 | S9: 6 | X9: 6 | Y9: 6 | Z9: =IFERROR(ROUND(AVERAGE(C9:Y9),1),"")
A10: 8 | B10: КОХ КОНДРАТ | C10: 9 | D10: 7 | E10: 7 | F10: 4 | G10: 7 | H10: 8 | I10: 6 | J10: 8 | K10: 7 | L10: 8 | M10: 6 | N10: 8 | O10: 8 | P10: 9 | Q10: 8 | R10: 10 | U10: 8 | X10: 8 | Y10: 8 | Z10: =IFERROR(ROUND(AVERAGE(C10:Y10),1),"")
A11: 9 | B11: КУЗНЕЦОВ РОМАН | C11: 6 | D11: 4 | E11: 6 | F11: 8 | G11: 6 | H11: 4 | I11: 7 | J11: 6 | K11: 6 | L11: 8 | M11: 6 | N11: 9 | O11: 6 | P11: 9 | S11: 8 | W11: 8 | Y11: 8 | Z11: =IFERROR(ROUND(AVERAGE(C11:Y11),1),"")
A12: 10 | B12: ПАЗНИКОВА ДАНАЯ | C12: 10 | D12: 9 | E12: 9 | F12: 9 | G12: 8 | H12: 9 | I12: 9 | J12: 9 | K12: 9 | L12: 10 | M12: 9 | N12: 10 | O12: 9 | P12: 10 | Q12: 8 | R12: 10 | S12: 10 | U12: 10 | W12: 10 | X12: 9 | Z12: =IFERROR(ROUND(AVERAGE(C12:Y12),1),"")
A13: 11 | B13: ПОДОЛЬСКИЙ АРТЁМ | C13: 9 | D13: 9 | E13: 9 | F13: 9 | G13: 9 | H13: 9 | I13: 9 | J13: 9 | K13: 9 | L13: 9 | M13: 9 | N13: 8 | O13: 9 | P13: 9 | Q13: 6 | R13: 10 | S13: 9 | U13: 10 | W13: 9 | Y13: 9 | Z13: =IFERROR(ROUND(AVERAGE(C13:Y13),1),"")
A14: 12 | B14: РАМЕНСКАЯ ВЕРОНИКА | C14: 6 | D14: 8 | E14: 9 | F14: 8 | G14: 8 | H14: 7 | I14: 10 | J14: 5 | K14: 9 | L14: 8 | M14: 10 | N14: 8 | O14: 9 | P14: 9 | Q14: 4 | R14: 10 | S14: 9 | T14: 8 | U14: 10 | W14: 9 | X14: 10 | Z14: =IFERROR(ROUND(AVERAGE(C14:Y14),1),"")
A15: 13 | B15: РОМАЗЕЕВА АЛЁНА | C15: 6 | D15: 6 | E15: 6 | F15: 6 | G15: 6 | H15: 6 | I15: 7 | J15: 6 | K15: 6 | L15: 8 | M15: 6 | N15: 8 | O15: 8 | R15: 10 | T15: 7 | U15: 5 | W15: 5 | Y15: 5 | Z15: =IFERROR(ROUND(AVERAGE(C15:Y15),1),"")
A16: 14 | B16: Романишина Ульяна | C16: 10 | D16: 9 | E16: 9 | F16: 9 | G16: 8 | H16: 9 | I16: 9 | J16: 9 | K16: 9 | L16: 10 | M16: 9 | N16: 10 | O16: 9 | P16: 10 | Q16: 8 | R16: 10 | S16: 10 | T16: 8 | U16: 10 | W16: 10 | X16: 9 | Y16: 10 | Z16: =IFERROR(ROUND(AVERAGE(C16:Y16),1),"")

Sheet 8А Геометрия
A1: 8А Геометрия — оценки (на 23.10.2026)
A2: № | B2: ФИО | C2: 01.09.26 | D2: 03.09.26 | E2: 08.09.26 | F2: 10.09.26 | G2: 15.09.26 | H2: 17.09.26 | I2: 22.09.26 | J2: 24.09.26 | K2: 29.09.26 | L2: 01.10.26 | M2: 06.10.26 | N2: 08.10.26 | O2: 13.10.26 СОР | P2: 15.10.26 СОЧ | Q2: 20.10.26 | R2: 22.10.26 | S2: Средний
A3: 1 | B3: Абельдинова Жасмин | C3: 9 | E3: 8 | F3: 6 | H3: 8 | I3: 8 | J3: 8 | K3: 9 | L3: 9 | M3: 8 | N3: 9 | Q3: 8 | S3: =IFERROR(ROUND(AVERAGE(C3:R3),1),"")
A4: 2 | B4: БЕРДНИКОВА ЕВГЕНИЯ | C4: 8 | E4: 7 | F4: 8 | G4: 7 | H4: 6 | J4: 7 | K4: 8 | L4: 7 | M4: 10 | N4: 9 | O4: 9 | R4: 8 | S4: =IFERROR(ROUND(AVERAGE(C4:R4),1),"")
A5: 3 | B5: БЕРДНИКОВА ДАРЬЯ | C5: 8 | D5: 7 | E5: 7 | F5: 8 | G5: 7 | H5: 8 | I5: 7 | J5: 6 | L5: 7 | M5: 9 | N5: 9 | Q5: 8 | R5: 8 | S5: =IFERROR(ROUND(AVERAGE(C5:R5),1),"")
A6: 4 | B6: БУЧКОВА МИЛАНА | C6: 8 | E6: 8 | F6: 8 | G6: 5 | H6: 7 | I6: 8 | J6: 9 | K6: 8 | L6: 9 | M6: 10 | N6: 9 | Q6: 8 | S6: =IFERROR(ROUND(AVERAGE(C6:R6),1),"")
A7: 5 | B7: ВАСИЛЬКОВСКИЙ ДАНИЛ | C7: 8 | D7: 7 | E7: 7 | G7: 9 | H7: 6 | I7: 7 | J7: 7 | L7: 9 | M7: 8 | N7: 9 | O7: 9 | Q7: 8 | R7: 8 | S7: =IFERROR(ROUND(AVERAGE(C7:R7),1),"")
A8: 6 | B8: ГАЛИПАД ДАНИЛ | C8: 5 | D8: 6 | F8: 5 | G8: 6 | H8: 6 | J8: 6 | K8: 6 | L8: 5 | M8: 6 | N8: 6 | R8: 6 | S8: =IFERROR(ROUND(AVERAGE(C8:R8),1),"")
A9: 7 | B9: КИСМЕТЬЕВ ИСЛАМ | C9: 5 | D9: 6 | F9: 7 | G9: 6 | H9: 5 | I9: 6 | J9: 7 | K9: 6 | N9: 6 | Q9: 6 | R9: 5 | S9: =IFERROR(ROUND(AVERAGE(C9:R9),1),"")
A10: 8 | B10: КОХ КОНДРАТ | C10: 9 | D10: 8 | E10: 8 | F10: 9 | G10: 8 | H10: 7 | I10: 10 | J10: 8 | K10: 8 | L10: 9 | M10: 8 | Q10: 8 | S10: =IFERROR(ROUND(AVERAGE(C10:R10),1),"")
A11: 9 | B11: КУЗНЕЦОВ РОМАН | C11: 5 | D11: 8 | E11: 6 | F11: 7 | G11: 4 | H11: 8 | I11: 6 | J11: 7 | K11: 8 | L11: 8 | O11: 8 | Q11: 8 | R11: 8 | S11: =IFERROR(ROUND(AVERAGE(C11:R11),1),"")
A12: 10 | B12: ПАЗНИКОВА ДАНАЯ | C12: 10 | D12: 10 | E12: 10 | F12: 9 | G12: 10 | H12: 10 | J12: 10 | K12: 9 | L12: 10 | M12: 10 | N12: 10 | O12: 10 | Q12: 10 | R12: 9 | S12: =IFERROR(ROUND(AVERAGE(C12:R12),1),"")
A13: 11 | B13: ПОДОЛЬСКИЙ АРТЁМ | C13: 10 | D13: 10 | F13: 9 | G13: 10 | H13: 10 | I13: 9 | J13: 10 | K13: 9 | L13: 10 | M13: 8 | N13: 9 | O13: 9 | Q13: 10 | S13: =IFERROR(ROUND(AVERAGE(C13:R13),1),"")
A14: 12 | B14: РАМЕНСКАЯ ВЕРОНИКА | C14: 8 | E14: 8 | F14: 6 | G14: 8 | H14: 8 | I14: 8 | K14: 9 | L14: 9 | M14: 10 | N14: 9 | O14: 9 | Q14: 8 | R14: 8 | S14: =IFERROR(ROUND(AVERAGE(C14:R14),1),"")
A15: 13 | B15: РОМАЗЕЕВА АЛЁНА | C15: 6 | E15: 6 | F15: 6 | G15: 6 | I15: 6 | J15: 6 | K15: 6 | L15: 6 | N15: 6 | R15: 6 | S15: =IFERROR(ROUND(AVERAGE(C15:R15),1),"")
A16: 14 | B16: Романишина Ульяна | C16: 10 | D16: 9 | E16: 10 | F16: 9 | G16: 10 | I16: 9 | J16: 9 | K16: 10 | L16: 10 | M16: 10 | N16: 10 | O16: 10 | R16: 9 | S16: =IFERROR(ROUND(AVERAGE(C16:R16),1),"")

Sheet 8Б Алгебра
A1: 8Б Алгебра — оценки (на 23.10.2026)
A2: № | B2: ФИО | C2: 02.09.26 | D2: 04.09.26 | E2: 07.09.26 | F2: 09.09.26 | G2: 11.09.26 | H2: 14.09.26 | I2: 16.09.26 | J2: 18.09.26 | K2: 21.09.26 | L2: 23.09.26 | M2: 25.09.26 | N2: 28.09.26 | O2: 30.09.26 | P2: 02.10.26 | Q2: 05.10.26 | R2: 07.10.26 | S2: 09.10.26 | T2: 12.10.26 СОР | U2: 14.10.26 | V2: 16.10.26 СОЧ | W2: 19.10.26 | X2: 21.10.26 | Y2: 23.10.26 | Z2: Средний
A3: 1 | B3: ГАЛЛЕ ВАЛЕРИЙ | C3: 5 | D3: 7 | F3: 9 | G3: 6 | H3: 7 | I3: 7 | L3: 7 | M3: 6 | P3: 7 | R3: 8 | U3: 6 | W3: 6 | X3: 5 | Z3: =IFERROR(ROUND(AVERAGE(C3:Y3),1),"")
A4: 2 | B4: ДОЙНЕКО СОФИЯ | C4: 9 | E4: 9 | F4: 9 | G4: 8 | H4: 9 | J4: 10 | K4: 9 | M4: 8 | N4: 9 | O4: 9 | P4: 10 | Q4: 9 | S4: 9 | T4: 7 | U4: 9 | W4: 9 | X4: 10 | Y4: 9 | Z4: =IFERROR(ROUND(AVERAGE(C4:Y4),1),"")
A5: 3 | B5: ЖЕЛНИНА ВЕРА | C5: 8 | D5: 7 | E5: 9 | G5: 8 | H5: 6 | I5: 9 | J5: 7 | K5: 9 | L5: 7 | M5: 7 | N5: 5 | O5: 9 | P5: 7 | Q5: 8 | R5: 8 | U5: 8 | X5: 8 | Y5: 8 | Z5: =IFERROR(ROUND(AVERAGE(C5:Y5),1),"")
A6: 4 | B6: ПОТАНИН ВАЛЕРИЙ | C6: 5 | E6: 6 | F6: 5 | H6: 5 | I6: 5 | J6: 6 | L6: 5 | M6: 5 | P6: 6 | R6: 8 | U6: 5 | Y6: 5 | Z6: =IFERROR(ROUND(AVERAGE(C6:Y6),1),"")
A7: 5 | B7: РОМАНОВА ЕВА | C7: 7 | D7: 8 | E7: 8 | F7: 6 | G7: 8 | H7: 9 | I7: 7 | J7: 6 | K7: 6 | L7: 7 | M7: 8 | N7: 6 | O7: 8 | P7: 8 | Q7: 7 | S7: 8 | T7: 9 | W7: 5 | X7: 9 | Y7: 5 | Z7: =IFERROR(ROUND(AVERAGE(C7:Y7),1),"")
A8: 6 | B8: САҒИТ ӘМІР | C8: 8 | D8: 9 | E8: 10 | F8: 9 | I8: 9 | J8: 9 | K8: 10 | L8: 9 | N8: 7 | O8: 8 | P8: 8 | Q8: 8 | S8: 6 | T8: 5 | U8: 8 | W8: 8 | Y8: 8 | Z8: =IFERROR(ROUND(AVERAGE(C8:Y8),1),"")
A9: 7 | B9: ТОРЧИНСКИЙ МАТВЕЙ | C9: 8 | D9: 7 | F9: 7 | G9: 8 | H9: 7 | I9: 8 | J9: 7 | K9: 7 | L9: 6 | M9: 7 | N9: 7 | O9: 7 | P9: 7 | Q9: 8 | S9: 8 | T9: 5 | U9: 8 | W9: 8 | X9: 8 | Y9: 8 | Z9: =IFERROR(ROUND(AVERAGE(C9:Y9),1),"")
A10: 8 | B10: ФОМИН МАКСИМ | C10: 10 | D10: 9 | E10: 9 | G10: 9 | H10: 9 | J10: 9 | K10: 9 | L10: 9 | M10: 9 | N10: 10 | P10: 10 | Q10: 8 | R10: 10 | T10: 9 | U10: 8 | W10: 8 | X10: 8 | Y10: 8 | Z10: =IFERROR(ROUND(AVERAGE(C10:Y10),1),"")
A11: 9 | B11: ЧАЙКА ТАИСИЯ | C11: 10 | D11: 10 | E11: 10 | F11: 9 | H11: 10 | I11: 10 | J11: 10 | K11: 10 | L11: 10 | M11: 10 | N11: 10 | O11: 10 | P11: 10 | Q11: 9 | R11: 10 | S11: 10 | T11: 10 | U11: 10 | W11: 10 | X11: 9 | Y11: 9 | Z11: =IFERROR(ROUND(AVERAGE(C11:Y11),1),"")
A12: 10 | B12: ШАРБАКПАЕВА АЙДАРИЯ | C12: 7 | D12: 8 | E12: 8 | F12: 6 | G12: 8 | H12: 9 | I12: 7 | K12: 6 | M12: 8 | N12: 7 | O12: 8 | P12: 8 | Q12: 6 | S12: 8 | T12: 9 | U12: 8 | W12: 8 | X12: 8 | Y12: 8 | Z12: =IFERROR(ROUND(AVERAGE(C12:Y12),1),"")
A13: 11 | B13: ШАРИПОВА ВЕРА | C13: 6 | D13: 8 | G13: 6 | J13: 10 | K13: 6 | L13: 6 | M13: 8 | O13: 6 | P13: 6 | Q13: 6 | R13: 8 | S13: 8 | W13: 6 | Y13: 5 | Z13: =IFERROR(ROUND(AVERAGE(C13:Y13),1),"")
A14: 12 | B14: ШИШ АРТЁМ | C14: 6 | D14: 6 | E14: 6 | F14: 7 | G14: 8 | H14: 6 | I14: 8 | J14: 6 | K14: 6 | L14: 7 | M14: 5 | N14: 6 | O14: 8 | P14: 6 | S14: 7 | T14: 6 | W14: 5 | X14: 6 | Z14: =IFERROR(ROUND(AVERAGE(C14:Y14),1),"")
A15: 13 | B15: ЩЕГЛОВ КИРИЛЛ | C15: 6 | E15: 6 | F15: 8 | G15: 6 | H15: 6 | I15: 6 | K15: 6 | L15: 6 | M15: 5 | O15: 6 | P15: 6 | Q15: 6 | S15: 6 | U15: 6 | X15: 5 | Z15: =IFERROR(ROUND(AVERAGE(C15:Y15),1),"")

Sheet 8Б Геометрия
A1: 8Б Геометрия — оценки (на 23.10.2026)
A2: № | B2: ФИО | C2: 01.09.26 | D2: 03.09.26 | E2: 08.09.26 | F2: 10.09.26 | G2: 15.09.26 | H2: 17.09.26 | I2: 22.09.26 | J2: 24.09.26 | K2: 29.09.26 | L2: 01.10.26 | M2: 06.10.26 | N2: 08.10.26 | O2: 13.10.26 СОР | P2: 15.10.26 СОЧ | Q2: 20.10.26 | R2: 22.10.26 | S2: Средний
A3: 1 | B3: ГАЛЛЕ ВАЛЕРИЙ | D3: 7 | F3: 9 | G3: 6 | H3: 7 | I3: 7 | K3: 6 | L3: 7 | N3: 4 | R3: 6 | S3: =IFERROR(ROUND(AVERAGE(C3:R3),1),"")
A4: 2 | B4: ДОЙНЕКО СОФИЯ | C4: 9 | E4: 9 | F4: 9 | G4: 8 | H4: 9 | J4: 10 | K4: 9 | L4: 10 | M4: 9 | N4: 7 | O4: 8 | Q4: 8 | S4: =IFERROR(ROUND(AVERAGE(C4:R4),1),"")
A5: 3 | B5: ЖЕЛНИНА ВЕРА | D5: 7 | E5: 9 | G5: 8 | H5: 6 | I5: 9 | J5: 7 | K5: 9 | L5: 7 | N5: 6 | Q5: 8 | S5: =IFERROR(ROUND(AVERAGE(C5:R5),1),"")
A6: 4 | B6: ПОТАНИН ВАЛЕРИЙ | C6: 5 | E6: 6 | F6: 5 | H6: 5 | I6: 5 | J6: 6 | L6: 5 | M6: 6 | N6: 4 | O6: 6 | Q6: 5 | R6: 6 | S6: =IFERROR(ROUND(AVERAGE(C6:R6),1),"")
A7: 5 | B7: РОМАНОВА ЕВА | D7: 8 | E7: 8 | F7: 6 | G7: 8 | H7: 9 | I7: 7 | J7: 6 | K7: 6 | L7: 7 | N7: 5 | Q7: 8 | S7: =IFERROR(ROUND(AVERAGE(C7:R7),1),"")
A8: 6 | B8: САҒИТ ӘМІР | C8: 8 | D8: 9 | E8: 10 | F8: 9 | H8: 8 | I8: 9 | J8: 9 | K8: 10 | L8: 8 | N8: 8 | R8: 8 | S8: =IFERROR(ROUND(AVERAGE(C8:R8),1),"")
A9: 7 | B9: ТОРЧИНСКИЙ МАТВЕЙ | D9: 7 | F9: 7 | G9: 8 | H9: 7 | I9: 8 | J9: 7 | K9: 7 | L9: 6 | M9: 9 | N9: 5 | Q9: 8 | R9: 8 | S9: =IFERROR(ROUND(AVERAGE(C9:R9),1),"")
A10: 8 | B10: ФОМИН МАКСИМ | C10: 10 | D10: 9 | E10: 9 | G10: 9 | H10: 9 | J10: 9 | K10: 9 | L10: 9 | N10: 8 | O10: 9 | Q10: 8 | S10: =IFERROR(ROUND(AVERAGE(C10:R10),1),"")
A11: 9 | B11: ЧАЙКА ТАИСИЯ | C11: 10 | D11: 10 | E11: 10 | F11: 10 | H11: 10 | I11: 10 | J11: 10 | K11: 10 | L11: 10 | M11: 10 | N11: 10 | O11: 10 | Q11: 10 | R11: 9 | S11: =IFERROR(ROUND(AVERAGE(C11:R11),1),"")
A12: 10 | B12: ШАРБАКПАЕВА АЙДАРИЯ | C12: 7 | D12: 8 | E12: 8 | F12: 6 | G12: 8 | H12: 9 | I12: 7 | K12: 6 | N12: 8 | Q12: 8 | R12: 8 | S12: =IFERROR(ROUND(AVERAGE(C12:R12),1),"")
A13: 11 | B13: ШАРИПОВА ВЕРА | C13: 6 | D13: 8 | F13: 6 | G13: 6 | H13: 7 | J13: 10 | K13: 8 | L13: 6 | N13: 6 | Q13: 6 | R13: 6 | S13: =IFERROR(ROUND(AVERAGE(C13:R13),1),"")
A14: 12 | B14: ШИШ АРТЁМ | D14: 6 | E14: 6 | F14: 7 | H14: 6 | I14: 8 | K14: 8 | L14: 7 | N14: 6 | Q14: 6 | R14: 6 | S14: =IFERROR(ROUND(AVERAGE(C14:R14),1),"")
A15: 13 | B15: ЩЕГЛОВ КИРИЛЛ | C15: 6 | E15: 6 | F15: 8 | G15: 6 | H15: 6 | I15: 6 | K15: 6 | L15: 6 | M15: 7 | N15: 5 | O15: 6 | R15: 5 | S15: =IFERROR(ROUND(AVERAGE(C15:R15),1),"")

Sheet 9Б Алгебра
A1: 9Б Алгебра — оценки (на 23.10.2026)
A2: № | B2: ФИО | C2: 02.09.26 | D2: 04.09.26 | E2: 07.09.26 | F2: 09.09.26 | G2: 11.09.26 | H2: 14.09.26 | I2: 16.09.26 | J2: 18.09.26 | K2: 21.09.26 | L2: 23.09.26 СОР | M2: 25.09.26 | N2: 28.09.26 | O2: 30.09.26 | P2: 02.10.26 | Q2: 05.10.26 | R2: 07.10.26 | S2: 09.10.26 | T2: 12.10.26 | U2: 14.10.26 СОР | V2: 16.10.26 СОЧ | W2: 19.10.26 | X2: 21.10.26 | Y2: 23.10.26 | Z2: Средний
A3: 1 | B3: АКАУОВ АНСАР | C3: 10 | D3: 9 | E3: 10 | F3: 9 | G3: 10 | H3: 10 | J3: 10 | K3: 9 | L3: 9 | M3: 10 | N3: 9 | O3: 10 | P3: 10 | Q3: 6 | R3: 9 | S3: 10 | T3: 9 | U3: 9 | W3: 10 | Z3: =IFERROR(ROUND(AVERAGE(C3:Y3),1),"")
A4: 2 | B4: БАЙЛЬДИНОВ ИСЛАМ | C4: 10 | D4: 10 | E4: 10 | F4: 10 | G4: 10 | H4: 10 | I4: 10 | J4: 10 | K4: 10 | M4: 10 | N4: 10 | O4: 10 | P4: 10 | Q4: 6 | R4: 10 | S4: 10 | T4: 10 | U4: 8 | Y4: 8 | Z4: =IFERROR(ROUND(AVERAGE(C4:Y4),1),"")
A5: 3 | B5: БАТУХТИНА ВИКТОРИЯ | D5: 6 | E5: 8 | G5: 6 | H5: 8 | I5: 8 | J5: 6 | K5: 6 | N5: 8 | O5: 6 | Q5: 4 | R5: 8 | T5: 8 | X5: 8 | Y5: 8 | Z5: =IFERROR(ROUND(AVERAGE(C5:Y5),1),"")
A6: 4 | B6: ГАЗИЕВ ТИМУР | C6: 8 | D6: 8 | E6: 8 | F6: 8 | G6: 9 | H6: 8 | J6: 8 | K6: 9 | L6: 8 | N6: 8 | O6: 9 | P6: 9 | S6: 9 | U6: 8 | W6: 8 | X6: 8 | Z6: =IFERROR(ROUND(AVERAGE(C6:Y6),1),"")
A7: 5 | B7: ГАНТИМУРОВА ЛЮБОВЬ | C7: 6 | D7: 6 | E7: 8 | F7: 4 | G7: 6 | I7: 8 | J7: 8 | K7: 8 | M7: 8 | N7: 7 | O7: 7 | P7: 10 | Q7: 5 | R7: 8 | U7: 8 | W7: 8 | Y7: 8 | Z7: =IFERROR(ROUND(AVERAGE(C7:Y7),1),"")
A8: 6 | B8: ДОЙНЕКО ЭРНЕСТ | D8: 8 | E8: 6 | F8: 8 | G8: 8 | H8: 6 | I8: 8 | J8: 7 | M8: 7 | N8: 8 | O8: 9 | P8: 9 | Q8: 8 | R8: 8 | U8: 8 | X8: 8 | Z8: =IFERROR(ROUND(AVERAGE(C8:Y8),1),"")
A9: 7 | B9: КАЙРУЛЛИН АРСЕНТИЙ | C9: 6 | E9: 6 | F9: 6 | G9: 6 | H9: 8 | I9: 6 | J9: 8 | K9: 6 | M9: 6 | N9: 6 | O9: 6 | P9: 6 | Q9: 4 | R9: 6 | S9: 8 | T9: 9 | W9: 6 | X9: 5 | Y9: 6 | Z9: =IFERROR(ROUND(AVERAGE(C9:Y9),1),"")
A10: 8 | B10: КОЗЛОВ ВАДИМ | C10: 8 | D10: 8 | E10: 8 | F10: 5 | H10: 8 | I10: 9 | J10: 8 | K10: 9 | N10: 8 | O10: 8 | P10: 9 | Q10: 7 | R10: 8 | S10: 8 | T10: 6 | U10: 6 | X10: 5 | Y10: 6 | Z10: =IFERROR(ROUND(AVERAGE(C10:Y10),1),"")
A11: 9 | B11: КОЛМОГОРОВА АНАСТАСИЯ | D11: 8 | E11: 8 | F11: 7 | G11: 8 | H11: 9 | I11: 9 | J11: 8 | K11: 6 | M11: 8 | N11: 9 | O11: 8 | P11: 10 | S11: 8 | T11: 8 | U11: 6 | X11: 5 | Y11: 5 | Z11: =IFERROR(ROUND(AVERAGE(C11:Y11),1),"")
A12: 10 | B12: КРАСНОПЕРОВА АМИНА | D12: 6 | E12: 6 | F12: 8 | G12: 8 | H12: 6 | J12: 6 | M12: 9 | N12: 7 | P12: 10 | Q12: 5 | T12: 8 | W12: 8 | X12: 8 | Z12: =IFERROR(ROUND(AVERAGE(C12:Y12),1),"")
A13: 11 | B13: КРАСНОПЕРОВА КАЛЕРИЯ | C13: 8 | D13: 8 | F13: 7 | G13: 8 | H13: 6 | I13: 8 | J13: 7 | K13: 8 | L13: 8 | M13: 9 | N13: 8 | O13: 9 | P13: 8 | Q13: 4 | R13: 8 | T13: 9 | U13: 8 | W13: 8 | X13: 8 | Y13: 8 | Z13: =IFERROR(ROUND(AVERAGE(C13:Y13),1),"")
